Workbook

Sheet Read me
A1: ISRM Partner Scope & Cost Model · input scaffold
A2: GBP is a working currency, not a confirmed contract currency. This is not a quote or approved budget. Unapproved effort, partner rates, supplier costs and decisions remain blank/TBD; open in a compatible spreadsheet application to recalculate formulas.
A4: Purpose | B4: Four independent commercial scopes, three partner roles, residual software effort and a separate graph/search replacement-value benchmark. Historical planning inputs are retained only in Work Breakdown notes and are inactive.
A5: Four circles | B5: 1 Consulting/strategy; 2 Application MVP; 3 bounded one-client pilot functionality; 4 other/post-pilot functionality. Each row is a distinct scope, not a low/base/high tier or cumulative offer.
A6: Three roles | B6: P1 Client communications & business development; P2 Operations, OSINT, events & external communications; P3 Product Owner, strategy & developer relationships.
A7: Three cost layers | B7: Partner work, residual software supplier work, a conditional client-facing graph/search replacement-value benchmark, a separately approved internal allocation, and quoted external costs. No reuse charge is automatic.
A8: Calculation | B8: Active person-hours = approved quantity × approved hours/unit. Cost = person-hours × agreed rate. Unknown status/inputs return TBD; only an explicit No/Excluded decision returns zero. Day conversions are assumptions, not effort estimates.
A9: Dossier scenario | B9: The 300–500 dossier capacity scenario is historical planning context only, not an approved pilot cohort or forecast. Current cohort and dossier effort remain TBD; do not multiply sample minutes by a capacity estimate.
A10: Rates | B10: Partner-rate and supplier-rate inputs are blank until partner-agreed rates or comparable-scope supplier quotations are provided. Source benchmarks remain context only and are not substituted as partner rates.
A11: Exclusions | B11: Graph/search replacement-value benchmark: 3/5/7 developer-days × published UK contractor median. Effort is [ASSUMPTION], not measured historical labor; the resulting amount is not a quote, licence price, partner fee or automatic client charge. Include only after a separate written decision.
A12: Software boundary | B12: Residual production software work is unestimated. Reconcile the exact demo build, acceptance criteria, data access and integrations before entering approved quantities/hours or supplier quotes.
A13: Color key | B13: Yellow = required editable input; green = formula; orange = assumption/decision. Blank/TBD is not zero. Use No/Excluded only for an explicit scope exclusion.

Sheet Inputs
A1: Editable inputs · partner decisions and evidenced values
A2: Blank/TBD means unknown, never zero. Enter partner rates only when agreed; enter supplier costs only from comparable quotes. GBP remains a working-currency assumption. Recalculate in a compatible spreadsheet application before relying on formula outputs.
A4: Input ID | B4: Value | C4: Unit | D4: Status | E4: Origin / method / caveat
A5: CURRENCY | B5: GBP | C5: currency code | D5: ASSUMPTION | E5: Working display currency only; confirm before contract.
A6: RATE_P1 | C6: GBP / partner-hour | D6: Partner input required · no default | E6: Reference only; not a partner rate or quote. YunoJuno 2025 report overall average £49/h (dataset 2022–2024); broad proxy, not partner quote.
A7: RATE_P2 | C7: GBP / partner-hour | D7: Partner input required · no default | E7: Reference only; not a partner rate or quote. YunoJuno 2025 report market-research average £61/h; adjacent proxy for operations/OSINT, not exact role match or quote.
A8: RATE_P3 | C8: GBP / partner-hour | D8: Partner input required · no default | E8: Reference only; not a partner rate or quote. YunoJuno 2025 report strategy average £65/h; Product Owner/strategy proxy, not partner quote.
A9: DEV_DAY_RATE_MID | C9: GBP / contractor-day | D9: Supplier quote required · no default | E9: Reference range only; not a supplier quote. Midpoint of Lorien UK software contractor range £400–£550/day; not supplier quote.
A10: DEV_HOURS_DAY | B10: 7.5 | C10: hours / contractor-day | D10: [ASSUMPTION] unit conversion only | E10: Conversion basis for a contractor-day comparator; not an effort estimate.
A11: DEV_HOURLY_RATE | B11: =IF(OR(B9="",B10=""),"TBD",B9/B10) | C11: GBP / supplier-hour | D11: FORMULA · comparator only | E11: Day rate ÷ hours/day; displays TBD until a sourced day rate is entered.
A12: PARTNER_HOURS_DAY | B12: 8 | C12: hours / working-day | D12: [ASSUMPTION] unit conversion only | E12: Conversion basis only; not a workday count or effort estimate.
A13: DOSSIER_RECORDS | C13: records / capacity scenario | D13: TBD · not an active cohort input | E13: A prior 300–500 capacity scenario and its midpoint are not an approved pilot cohort or expected participation. Do not use in costs or forecast.
A14: DOSSIER_MEASURE_SOURCE | B14: =IF('Dossier Measurement'!D5="","",'Dossier Measurement'!D5) | C14: observed person-minutes in timed sample | D14: MEASUREMENT LOG · NOT PRICE INPUT | E14: Observed Source gathering time; see Dossier Measurement. Never multiply sample hours by the capacity scenario automatically.
A15: DOSSIER_MEASURE_RECON | B15: =IF('Dossier Measurement'!D6="","",'Dossier Measurement'!D6) | C15: observed person-minutes in timed sample | D15: MEASUREMENT LOG · NOT PRICE INPUT | E15: Observed Reconciliation / evidence review time; see Dossier Measurement. Never multiply sample hours by the capacity scenario automatically.
A16: DOSSIER_MEASURE_CORRECTION | B16: =IF('Dossier Measurement'!D7="","",'Dossier Measurement'!D7) | C16: observed person-minutes in timed sample | D16: MEASUREMENT LOG · NOT PRICE INPUT | E16: Observed Correction / appeal time; see Dossier Measurement. Never multiply sample hours by the capacity scenario automatically.
A17: REUSE_AMOUNT | C17: GBP / one-time | D17: Partner decision required | E17: Optional internal allocation related to graph/search reuse only if separately agreed; not a client-facing fee and not inferred from historical work.
A18: REUSE_STATUS | B18: Decision required | C18: Include / Excluded / Decision required | D18: PARTNER DECISION | E18: Internal fee for author of the existing graph/search demonstration module, only if this client work reuses it and partners agree the fee. Not a separate client price line if already covered by the contract total; no historic hours or fee inferred.
A19: EXTERNAL_AMOUNT | C19: GBP / one-time | D19: Supplier quote required | E19: No verified external quote; leave blank until received. An explicit Excluded status is a scope decision, not a claim of free service.
A20: EXTERNAL_STATUS | B20: Decision required | C20: Include / Excluded / Decision required | D20: QUOTE REQUIRED | E20: Include only when amount is confirmed.
A21: TAX_STATUS | B21: Decision required | C21: Included / Excluded | D21: DECISION REQUIRED | E21: Tax treatment is not modeled or inferred.
A22: DOSSIER_MEASURE_APPROVAL | B22: =IF('Dossier Measurement'!D8="","",'Dossier Measurement'!D8) | C22: observed person-minutes in timed sample | D22: MEASUREMENT LOG · NOT PRICE INPUT | E22: Observed Client approval time; see Dossier Measurement. Never multiply sample hours by the capacity scenario automatically.
A23: Reusable graph + expert search · replacement-cost benchmark
A24: Input ID | B24: Value | C24: Unit | D24: Status | E24: Origin / method / caveat
A25: REUSE_EFFORT_BASE | B25: =B40 | C25: developer-days | D25: [ASSUMPTION] estimate | E25: Sum of the four scoped work packages below; not a time-tracked retrospective.
A26: REUSE_EFFORT_LOW | B26: 3 | C26: developer-days | D26: [ASSUMPTION] range | E26: Lower planning case; validate with a developer.
A27: REUSE_EFFORT_HIGH | B27: 7 | C27: developer-days | D27: [ASSUMPTION] range | E27: Upper planning case; validate with a developer.
A28: REUSE_UK_DEV_DAY_RATE | B28: 525 | C28: GBP / developer-day | D28: SOURCE · market median | E28: ITJobsWatch UK Software Developer contractor median, 6 months to 2026-10-05; 256 daily rates quoted. Not a supplier quote.
A29: REUSE_PRICE_LOW | B29: =B26*B28 | C29: GBP / one-time | D29: FORMULA · indicative | E29: Low effort × published UK median day rate; excludes VAT, hosting, licences, maintenance and support.
A30: GRAPH_SEARCH_REUSE_ALLOCATION | B30: =B25*B28 | C30: contract currency; one-time internal allocation | D30: Partner decision required | E30: Optional internal allocation only; not an additional client fee. Set only after written partner agreement; do not infer historic payment or hours.
A31: REUSE_PRICE_HIGH | B31: =B27*B28 | C31: GBP / one-time | D31: FORMULA · indicative | E31: High effort × published UK median day rate; excludes VAT, hosting, licences, maintenance and support.
A32: REUSE_CLIENT_LINE_STATUS | B32: Decision required | C32: Include / Exclude | D32: DECISION REQUIRED · not auto-included | E32: Separate client-facing graph/search replacement-value line in Scope 2 only if expressly included by written partner/client agreement. Exclude only by an explicit decision or if already covered by the accepted total.
A34: Replacement-effort estimate · work breakdown (planning estimate, not measured historic hours)
A35: Activity | B35: Developer-days | C35: Included scope | D35: Status
A36: Graph rendering, layers and node interactions | B36: 1.5 | C36: NetworkGraph: graph canvas, data-to-node/link mapping, layer toggles, focus/hover interactions. | D36: [ASSUMPTION]
A37: Expert search and filter controls | B37: 1 | C37: Text search plus verification, sector, geography, theme and role filters. | D37: [ASSUMPTION]
A38: Expert data shaping and access plumbing | B38: 1 | C38: Searchable record fields, server-side data shaping and network/access functions. | D38: [ASSUMPTION]
A39: Integration, responsive behavior and verification | B39: 1.5 | C39: Connect graph and filters, tune display/interaction, regression and refinement. | D39: [ASSUMPTION]
A40: Estimated base effort | B40: =SUM(B36:B39) | C40: developer-days | D40: [ASSUMPTION] estimate | E40: Effort is estimated from the inspected implementation scope. Source history proves a 9d 5h 27m calendar span between first and latest relevant file edits, not paid developer hours.

Sheet Work Breakdown
A1: New work breakdown · editable person-hour assumptions
A2: No historic hours imported. Edit quantity, hours/unit, inclusion or rates. Formula: included hours × hourly rate.
A4: Scope ID | B4: Commercial scope | C4: Work ID | D4: Cost layer | E4: Role ID | F4: Proposed deliverable / task | G4: Approved quantity (blank = TBD) | H4: Unit | I4: Approved hours/unit (blank = TBD) | J4: Person-hours | K4: Agreed rate (GBP/h) | L4: Calculated cost (GBP) | M4: Scope decision (Yes/No/TBD) | N4: Source / historical note / caveat
A5: 1 | B5: Consulting | C5: C-P1-01 | D5: Partner | E5: P1 | F5: Client/board discovery and decision preparation | H5: working session | J5: =IF($M5="No",0,IF($M5<>"Yes","TBD",IF(OR(NOT(ISNUMBER(G5)),NOT(ISNUMBER(I5))),"TBD",G5*I5))) | K5: =IF($M5="No",0,IF($M5<>"Yes","TBD",IF($E5="P1",IF(Inputs!$B$6="","TBD",Inputs!$B$6),IF($E5="P2",IF(Inputs!$B$7="","TBD",Inputs!$B$7),IF($E5="P3",IF(Inputs!$B$8="","TBD",Inputs!$B$8),IF($E5="DEV",IF(Inputs!$B$11="","TBD",Inputs!$B$11),"TBD")))))) | L5: =IF($M5="No",0,IF($M5<>"Yes","TBD",IF(OR(J5="TBD",K5="TBD"),"TBD",J5*K5))) | M5: TBD | N5: [ASSUMPTION] Two sessions including preparation and decision capture; 4 hours each. Prior planning inputs archived, inactive: quantity=2; hours/unit=4. [ASSUMPTION, not measured or approved.] Re-enter reviewed values before setting Yes.
A6: 1 | B6: Consulting | C6: C-P1-02 | D6: Partner | E6: P1 | F6: Write scope and decision summary for partner review | H6: written deliverable | J6: =IF($M6="No",0,IF($M6<>"Yes","TBD",IF(OR(NOT(ISNUMBER(G6)),NOT(ISNUMBER(I6))),"TBD",G6*I6))) | K6: =IF($M6="No",0,IF($M6<>"Yes","TBD",IF($E6="P1",IF(Inputs!$B$6="","TBD",Inputs!$B$6),IF($E6="P2",IF(Inputs!$B$7="","TBD",Inputs!$B$7),IF($E6="P3",IF(Inputs!$B$8="","TBD",Inputs!$B$8),IF($E6="DEV",IF(Inputs!$B$11="","TBD",Inputs!$B$11),"TBD")))))) | L6: =IF($M6="No",0,IF($M6<>"Yes","TBD",IF(OR(J6="TBD",K6="TBD"),"TBD",J6*K6))) | M6: TBD | N6: [ASSUMPTION] One concise synthesis deliverable; 8 hours. Prior planning inputs archived, inactive: quantity=1; hours/unit=8. [ASSUMPTION, not measured or approved.] Re-enter reviewed values before setting Yes.
A7: 1 | B7: Consulting | C7: C-P2-01 | D7: Partner | E7: P2 | F7: Design authorized outreach, response and evidence-record process | H7: working day | J7: =IF($M7="No",0,IF($M7<>"Yes","TBD",IF(OR(NOT(ISNUMBER(G7)),NOT(ISNUMBER(I7))),"TBD",G7*I7))) | K7: =IF($M7="No",0,IF($M7<>"Yes","TBD",IF($E7="P1",IF(Inputs!$B$6="","TBD",Inputs!$B$6),IF($E7="P2",IF(Inputs!$B$7="","TBD",Inputs!$B$7),IF($E7="P3",IF(Inputs!$B$8="","TBD",Inputs!$B$8),IF($E7="DEV",IF(Inputs!$B$11="","TBD",Inputs!$B$11),"TBD")))))) | L7: =IF($M7="No",0,IF($M7<>"Yes","TBD",IF(OR(J7="TBD",K7="TBD"),"TBD",J7*K7))) | M7: TBD | N7: [ASSUMPTION] Two 8-hour days for process design; excludes campaign execution. Prior planning inputs archived, inactive: quantity=2; hours/unit='=Inputs!$B$12'. [ASSUMPTION, not measured or approved.] Re-enter reviewed values before setting Yes.
A8: 1 | B8: Consulting | C8: C-P3-01 | D8: Partner | E8: P3 | F8: Prepare Trust & Influence strategic session | H8: working day | J8: =IF($M8="No",0,IF($M8<>"Yes","TBD",IF(OR(NOT(ISNUMBER(G8)),NOT(ISNUMBER(I8))),"TBD",G8*I8))) | K8: =IF($M8="No",0,IF($M8<>"Yes","TBD",IF($E8="P1",IF(Inputs!$B$6="","TBD",Inputs!$B$6),IF($E8="P2",IF(Inputs!$B$7="","TBD",Inputs!$B$7),IF($E8="P3",IF(Inputs!$B$8="","TBD",Inputs!$B$8),IF($E8="DEV",IF(Inputs!$B$11="","TBD",Inputs!$B$11),"TBD")))))) | L8: =IF($M8="No",0,IF($M8<>"Yes","TBD",IF(OR(J8="TBD",K8="TBD"),"TBD",J8*K8))) | M8: TBD | N8: [SOURCE RANGE + ASSUMPTION] Source states 2–3 preparation days for one preparer; 2.5 midpoint × 8 hours/day = 20 hours. Preparation only. Prior planning inputs archived, inactive: quantity=2.5; hours/unit='=Inputs!$B$12'. [ASSUMPTION, not measured or approved.] Re-enter reviewed values before setting Yes.
A9: 1 | B9: Consulting | C9: C-P3-02 | D9: Partner | E9: P3 | F9: Facilitate strategic session and synthesize decisions | H9: session package | J9: =IF($M9="No",0,IF($M9<>"Yes","TBD",IF(OR(NOT(ISNUMBER(G9)),NOT(ISNUMBER(I9))),"TBD",G9*I9))) | K9: =IF($M9="No",0,IF($M9<>"Yes","TBD",IF($E9="P1",IF(Inputs!$B$6="","TBD",Inputs!$B$6),IF($E9="P2",IF(Inputs!$B$7="","TBD",Inputs!$B$7),IF($E9="P3",IF(Inputs!$B$8="","TBD",Inputs!$B$8),IF($E9="DEV",IF(Inputs!$B$11="","TBD",Inputs!$B$11),"TBD")))))) | L9: =IF($M9="No",0,IF($M9<>"Yes","TBD",IF(OR(J9="TBD",K9="TBD"),"TBD",J9*K9))) | M9: TBD | N9: [ASSUMPTION] Facilitation, notes and synthesis; distinct from preparation. Prior planning inputs archived, inactive: quantity=1; hours/unit=12. [ASSUMPTION, not measured or approved.] Re-enter reviewed values before setting Yes.
A10: 1 | B10: Consulting | C10: C-P3-03 | D10: Partner | E10: P3 | F10: Draft co-designed Trust & Influence model and protocol | H10: working day | J10: =IF($M10="No",0,IF($M10<>"Yes","TBD",IF(OR(NOT(ISNUMBER(G10)),NOT(ISNUMBER(I10))),"TBD",G10*I10))) | K10: =IF($M10="No",0,IF($M10<>"Yes","TBD",IF($E10="P1",IF(Inputs!$B$6="","TBD",Inputs!$B$6),IF($E10="P2",IF(Inputs!$B$7="","TBD",Inputs!$B$7),IF($E10="P3",IF(Inputs!$B$8="","TBD",Inputs!$B$8),IF($E10="DEV",IF(Inputs!$B$11="","TBD",Inputs!$B$11),"TBD")))))) | L10: =IF($M10="No",0,IF($M10<>"Yes","TBD",IF(OR(J10="TBD",K10="TBD"),"TBD",J10*K10))) | M10: TBD | N10: [ASSUMPTION] Two days for first draft; not external validation or validated sector index. Prior planning inputs archived, inactive: quantity=2; hours/unit='=Inputs!$B$12'. [ASSUMPTION, not measured or approved.] Re-enter reviewed values before setting Yes.
A11: 2 | B11: Application MVP | C11: M-P1-01 | D11: Partner | E11: P1 | F11: Confirm user workflow and acceptance decisions for MVP | H11: working session | J11: =IF($M11="No",0,IF($M11<>"Yes","TBD",IF(OR(NOT(ISNUMBER(G11)),NOT(ISNUMBER(I11))),"TBD",G11*I11))) | K11: =IF($M11="No",0,IF($M11<>"Yes","TBD",IF($E11="P1",IF(Inputs!$B$6="","TBD",Inputs!$B$6),IF($E11="P2",IF(Inputs!$B$7="","TBD",Inputs!$B$7),IF($E11="P3",IF(Inputs!$B$8="","TBD",Inputs!$B$8),IF($E11="DEV",IF(Inputs!$B$11="","TBD",Inputs!$B$11),"TBD")))))) | L11: =IF($M11="No",0,IF($M11<>"Yes","TBD",IF(OR(J11="TBD",K11="TBD"),"TBD",J11*K11))) | M11: TBD | N11: [ASSUMPTION] Two review sessions; client owns final decisions. Prior planning inputs archived, inactive: quantity=2; hours/unit=4. [ASSUMPTION, not measured or approved.] Re-enter reviewed values before setting Yes.
A12: 2 | B12: Application MVP | C12: M-P2-01 | D12: Partner | E12: P2 | F12: Define approved data reconciliation and first-contact operating steps | H12: working day | J12: =IF($M12="No",0,IF($M12<>"Yes","TBD",IF(OR(NOT(ISNUMBER(G12)),NOT(ISNUMBER(I12))),"TBD",G12*I12))) | K12: =IF($M12="No",0,IF($M12<>"Yes","TBD",IF($E12="P1",IF(Inputs!$B$6="","TBD",Inputs!$B$6),IF($E12="P2",IF(Inputs!$B$7="","TBD",Inputs!$B$7),IF($E12="P3",IF(Inputs!$B$8="","TBD",Inputs!$B$8),IF($E12="DEV",IF(Inputs!$B$11="","TBD",Inputs!$B$11),"TBD")))))) | L12: =IF($M12="No",0,IF($M12<>"Yes","TBD",IF(OR(J12="TBD",K12="TBD"),"TBD",J12*K12))) | M12: TBD | N12: [ASSUMPTION] Two days to document human review and permissioned operations. Prior planning inputs archived, inactive: quantity=2; hours/unit='=Inputs!$B$12'. [ASSUMPTION, not measured or approved.] Re-enter reviewed values before setting Yes.
A13: 2 | B13: Application MVP | C13: M-P3-01 | D13: Partner | E13: P3 | F13: Translate accepted MVP scope into backlog and coordinate supplier | H13: working day | J13: =IF($M13="No",0,IF($M13<>"Yes","TBD",IF(OR(NOT(ISNUMBER(G13)),NOT(ISNUMBER(I13))),"TBD",G13*I13))) | K13: =IF($M13="No",0,IF($M13<>"Yes","TBD",IF($E13="P1",IF(Inputs!$B$6="","TBD",Inputs!$B$6),IF($E13="P2",IF(Inputs!$B$7="","TBD",Inputs!$B$7),IF($E13="P3",IF(Inputs!$B$8="","TBD",Inputs!$B$8),IF($E13="DEV",IF(Inputs!$B$11="","TBD",Inputs!$B$11),"TBD")))))) | L13: =IF($M13="No",0,IF($M13<>"Yes","TBD",IF(OR(J13="TBD",K13="TBD"),"TBD",J13*K13))) | M13: TBD | N13: [ASSUMPTION] Four days for PO/dependency/acceptance coordination; excludes coding. Prior planning inputs archived, inactive: quantity=4; hours/unit='=Inputs!$B$12'. [ASSUMPTION, not measured or approved.] Re-enter reviewed values before setting Yes.
A14: 2 | B14: Application MVP | C14: M-DEV-01 | D14: Software | E14: DEV | F14: Reconcile exact demonstration build against production requirements | H14: contractor day | J14: =IF($M14="No",0,IF($M14<>"Yes","TBD",IF(OR(NOT(ISNUMBER(G14)),NOT(ISNUMBER(I14))),"TBD",G14*I14))) | K14: =IF($M14="No",0,IF($M14<>"Yes","TBD",IF($E14="P1",IF(Inputs!$B$6="","TBD",Inputs!$B$6),IF($E14="P2",IF(Inputs!$B$7="","TBD",Inputs!$B$7),IF($E14="P3",IF(Inputs!$B$8="","TBD",Inputs!$B$8),IF($E14="DEV",IF(Inputs!$B$11="","TBD",Inputs!$B$11),"TBD")))))) | L14: =IF($M14="No",0,IF($M14<>"Yes","TBD",IF(OR(J14="TBD",K14="TBD"),"TBD",J14*K14))) | M14: TBD | N14: [ASSUMPTION] Demo inventory and residual-work validation; not a full rebuild. Prior planning inputs archived, inactive: quantity=2; hours/unit='=Inputs!$B$10'. [ASSUMPTION, not measured or approved.] Re-enter reviewed values before setting Yes.
A15: 2 | B15: Application MVP | C15: M-DEV-02 | D15: Software | E15: DEV | F15: Persist named groups and project assignments | H15: contractor day | J15: =IF($M15="No",0,IF($M15<>"Yes","TBD",IF(OR(NOT(ISNUMBER(G15)),NOT(ISNUMBER(I15))),"TBD",G15*I15))) | K15: =IF($M15="No",0,IF($M15<>"Yes","TBD",IF($E15="P1",IF(Inputs!$B$6="","TBD",Inputs!$B$6),IF($E15="P2",IF(Inputs!$B$7="","TBD",Inputs!$B$7),IF($E15="P3",IF(Inputs!$B$8="","TBD",Inputs!$B$8),IF($E15="DEV",IF(Inputs!$B$11="","TBD",Inputs!$B$11),"TBD")))))) | L15: =IF($M15="No",0,IF($M15<>"Yes","TBD",IF(OR(J15="TBD",K15="TBD"),"TBD",J15*K15))) | M15: TBD | N15: [ASSUMPTION] Persistence and project linkage; verify after code review. Prior planning inputs archived, inactive: quantity=6; hours/unit='=Inputs!$B$10'. [ASSUMPTION, not measured or approved.] Re-enter reviewed values before setting Yes.
A16: 2 | B16: Application MVP | C16: M-DEV-03 | D16: Software | E16: DEV | F16: Implement approved data upload, validation and human reconciliation workflow | H16: contractor day | J16: =IF($M16="No",0,IF($M16<>"Yes","TBD",IF(OR(NOT(ISNUMBER(G16)),NOT(ISNUMBER(I16))),"TBD",G16*I16))) | K16: =IF($M16="No",0,IF($M16<>"Yes","TBD",IF($E16="P1",IF(Inputs!$B$6="","TBD",Inputs!$B$6),IF($E16="P2",IF(Inputs!$B$7="","TBD",Inputs!$B$7),IF($E16="P3",IF(Inputs!$B$8="","TBD",Inputs!$B$8),IF($E16="DEV",IF(Inputs!$B$11="","TBD",Inputs!$B$11),"TBD")))))) | L16: =IF($M16="No",0,IF($M16<>"Yes","TBD",IF(OR(J16="TBD",K16="TBD"),"TBD",J16*K16))) | M16: TBD | N16: [ASSUMPTION] One agreed input format and review workflow. Prior planning inputs archived, inactive: quantity=5; hours/unit='=Inputs!$B$10'. [ASSUMPTION, not measured or approved.] Re-enter reviewed values before setting Yes.
... A25: 3 | B25: Pilot functionality | C25: P-P2-04 | D25: Partner | E25: P2 | F25: Synthesize survey and campaign responses | H25: working day | J25: =IF($M25="No",0,IF($M25<>"Yes","TBD",IF(OR(NOT(ISNUMBER(G25)),NOT(ISNUMBER(I25))),"TBD",G25*I25))) | K25: =IF($M25="No",0,IF($M25<>"Yes","TBD",IF($E25="P1",IF(Inputs!$B$6="","TBD",Inputs!$B$6),IF($E25="P2",IF(Inputs!$B$7="","TBD",Inputs!$B$7),IF($E25="P3",IF(Inputs!$B$8="","TBD",Inputs!$B$8),IF($E25="DEV",IF(Inputs!$B$11="","TBD",Inputs!$B$11),"TBD")))))) | L25: =IF($M25="No",0,IF($M25<>"Yes","TBD",IF(OR(J25="TBD",K25="TBD"),"TBD",J25*K25))) | M25: TBD | N25: [ASSUMPTION] Response volume and report depth may change effort. Prior planning inputs archived, inactive: quantity=3; hours/unit='=Inputs!$B$12'. [ASSUMPTION, not measured or approved.] Re-enter reviewed values before setting Yes.
A26: 3 | B26: Pilot functionality | C26: P-P2-05 | D26: Partner | F26: Measured dossier activities (excluded until sample and role allocation) | H26: scope marker (not record count) | J26: =IF($M26="No",0,IF($M26<>"Yes","TBD",IF(OR(NOT(ISNUMBER(G26)),NOT(ISNUMBER(I26))),"TBD",G26*I26))) | K26: =IF($M26="No",0,IF($M26<>"Yes","TBD",IF($E26="P1",IF(Inputs!$B$6="","TBD",Inputs!$B$6),IF($E26="P2",IF(Inputs!$B$7="","TBD",Inputs!$B$7),IF($E26="P3",IF(Inputs!$B$8="","TBD",Inputs!$B$8),IF($E26="DEV",IF(Inputs!$B$11="","TBD",Inputs!$B$11),"TBD")))))) | L26: =IF($M26="No",0,IF($M26<>"Yes","TBD",IF(OR(J26="TBD",K26="TBD"),"TBD",J26*K26))) | M26: TBD | N26: [MEASUREMENT REQUIRED] Partner decision input §5 prohibits assumed minutes or pricing the 300–500 capacity scenario before a permitted sample is timed. Record observed time by activity/role in Dossier Measurement. This sample log does not estimate the full pilot workload. Add priced work only after scope, role, measured basis and any extrapolation method are explicitly reviewed; never scale sample hours by 400 automatically. Prior planning inputs archived, inactive: quantity=1; hours/unit=None. [ASSUMPTION, not measured or approved.] Re-enter reviewed values before setting Yes.
A27: 3 | B27: Pilot functionality | C27: P-P3-01 | D27: Partner | E27: P3 | F27: Coordinate pilot product backlog, delivery decisions and acceptance | H27: working day | J27: =IF($M27="No",0,IF($M27<>"Yes","TBD",IF(OR(NOT(ISNUMBER(G27)),NOT(ISNUMBER(I27))),"TBD",G27*I27))) | K27: =IF($M27="No",0,IF($M27<>"Yes","TBD",IF($E27="P1",IF(Inputs!$B$6="","TBD",Inputs!$B$6),IF($E27="P2",IF(Inputs!$B$7="","TBD",Inputs!$B$7),IF($E27="P3",IF(Inputs!$B$8="","TBD",Inputs!$B$8),IF($E27="DEV",IF(Inputs!$B$11="","TBD",Inputs!$B$11),"TBD")))))) | L27: =IF($M27="No",0,IF($M27<>"Yes","TBD",IF(OR(J27="TBD",K27="TBD"),"TBD",J27*K27))) | M27: TBD | N27: [ASSUMPTION] Product ownership across bounded pilot. Prior planning inputs archived, inactive: quantity=4; hours/unit='=Inputs!$B$12'. [ASSUMPTION, not measured or approved.] Re-enter reviewed values before setting Yes.
A28: 3 | B28: Pilot functionality | C28: P-DEV-01 | D28: Software | E28: DEV | F28: Implement invitation, permission, response and participant-status workflow | H28: contractor day | J28: =IF($M28="No",0,IF($M28<>"Yes","TBD",IF(OR(NOT(ISNUMBER(G28)),NOT(ISNUMBER(I28))),"TBD",G28*I28))) | K28: =IF($M28="No",0,IF($M28<>"Yes","TBD",IF($E28="P1",IF(Inputs!$B$6="","TBD",Inputs!$B$6),IF($E28="P2",IF(Inputs!$B$7="","TBD",Inputs!$B$7),IF($E28="P3",IF(Inputs!$B$8="","TBD",Inputs!$B$8),IF($E28="DEV",IF(Inputs!$B$11="","TBD",Inputs!$B$11),"TBD")))))) | L28: =IF($M28="No",0,IF($M28<>"Yes","TBD",IF(OR(J28="TBD",K28="TBD"),"TBD",J28*K28))) | M28: TBD | N28: [ASSUMPTION] One approved outreach channel and participant-status flow. Prior planning inputs archived, inactive: quantity=5; hours/unit='=Inputs!$B$10'. [ASSUMPTION, not measured or approved.] Re-enter reviewed values before setting Yes.
A29: 4 | B29: Other / post-pilot functionality | C29: F-DEV-PAY-01 | D29: Software | E29: DEV | F29: Optional post-pilot payment integration; not required for the one-client pilot. | H29: contractor day | J29: =IF($M29="No",0,IF($M29<>"Yes","TBD",IF(OR(NOT(ISNUMBER(G29)),NOT(ISNUMBER(I29))),"TBD",G29*I29))) | K29: =IF($M29="No",0,IF($M29<>"Yes","TBD",IF($E29="P1",IF(Inputs!$B$6="","TBD",Inputs!$B$6),IF($E29="P2",IF(Inputs!$B$7="","TBD",Inputs!$B$7),IF($E29="P3",IF(Inputs!$B$8="","TBD",Inputs!$B$8),IF($E29="DEV",IF(Inputs!$B$11="","TBD",Inputs!$B$11),"TBD")))))) | L29: =IF($M29="No",0,IF($M29<>"Yes","TBD",IF(OR(J29="TBD",K29="TBD"),"TBD",J29*K29))) | M29: TBD | N29: [RECLASSIFIED from historical P-DEV-02 pilot row; inactive until separately scoped and approved.] [ASSUMPTION] One membership type and provider; fees, legal/tax work and onboarding excluded. Prior planning inputs archived, inactive: quantity=8; hours/unit='=Inputs!$B$10'. [ASSUMPTION, not measured or approved.] Re-enter reviewed values before setting Yes.
A30: 3 | B30: Pilot functionality | C30: P-DEV-03 | D30: Software | E30: DEV | F30: Implement pilot event/activity participation status | H30: contractor day | J30: =IF($M30="No",0,IF($M30<>"Yes","TBD",IF(OR(NOT(ISNUMBER(G30)),NOT(ISNUMBER(I30))),"TBD",G30*I30))) | K30: =IF($M30="No",0,IF($M30<>"Yes","TBD",IF($E30="P1",IF(Inputs!$B$6="","TBD",Inputs!$B$6),IF($E30="P2",IF(Inputs!$B$7="","TBD",Inputs!$B$7),IF($E30="P3",IF(Inputs!$B$8="","TBD",Inputs!$B$8),IF($E30="DEV",IF(Inputs!$B$11="","TBD",Inputs!$B$11),"TBD")))))) | L30: =IF($M30="No",0,IF($M30<>"Yes","TBD",IF(OR(J30="TBD",K30="TBD"),"TBD",J30*K30))) | M30: TBD | N30: [ASSUMPTION] Bounded activity and attendance status. Prior planning inputs archived, inactive: quantity=4; hours/unit='=Inputs!$B$10'. [ASSUMPTION, not measured or approved.] Re-enter reviewed values before setting Yes.
A31: 3 | B31: Pilot functionality | C31: P-DEV-04 | D31: Software | E31: DEV | F31: Implement pilot measures and outcome view | H31: contractor day | J31: =IF($M31="No",0,IF($M31<>"Yes","TBD",IF(OR(NOT(ISNUMBER(G31)),NOT(ISNUMBER(I31))),"TBD",G31*I31))) | K31: =IF($M31="No",0,IF($M31<>"Yes","TBD",IF($E31="P1",IF(Inputs!$B$6="","TBD",Inputs!$B$6),IF($E31="P2",IF(Inputs!$B$7="","TBD",Inputs!$B$7),IF($E31="P3",IF(Inputs!$B$8="","TBD",Inputs!$B$8),IF($E31="DEV",IF(Inputs!$B$11="","TBD",Inputs!$B$11),"TBD")))))) | L31: =IF($M31="No",0,IF($M31<>"Yes","TBD",IF(OR(J31="TBD",K31="TBD"),"TBD",J31*K31))) | M31: TBD | N31: [ASSUMPTION] Agreed definitions and bounded dashboard; no causal impact assumed. Prior planning inputs archived, inactive: quantity=4; hours/unit='=Inputs!$B$10'. [ASSUMPTION, not measured or approved.] Re-enter reviewed values before setting Yes.
A32: 3 | B32: Pilot functionality | C32: P-DEV-05 | D32: Software | E32: DEV | F32: Test, security check and handover for pilot additions | H32: contractor day | J32: =IF($M32="No",0,IF($M32<>"Yes","TBD",IF(OR(NOT(ISNUMBER(G32)),NOT(ISNUMBER(I32))),"TBD",G32*I32))) | K32: =IF($M32="No",0,IF($M32<>"Yes","TBD",IF($E32="P1",IF(Inputs!$B$6="","TBD",Inputs!$B$6),IF($E32="P2",IF(Inputs!$B$7="","TBD",Inputs!$B$7),IF($E32="P3",IF(Inputs!$B$8="","TBD",Inputs!$B$8),IF($E32="DEV",IF(Inputs!$B$11="","TBD",Inputs!$B$11),"TBD")))))) | L32: =IF($M32="No",0,IF($M32<>"Yes","TBD",IF(OR(J32="TBD",K32="TBD"),"TBD",J32*K32))) | M32: TBD | N32: [ASSUMPTION] Incremental checks and handover; not production security certification. Prior planning inputs archived, inactive: quantity=3; hours/unit='=Inputs!$B$10'. [ASSUMPTION, not measured or approved.] Re-enter reviewed values before setting Yes.
A33: 4 | B33: All remaining functionality | C33: F-P1-01 | D33: Partner | E33: P1 | F33: Coordinate future client/service opportunities and commercial decisions | H33: working day | J33: =IF($M33="No",0,IF($M33<>"Yes","TBD",IF(OR(NOT(ISNUMBER(G33)),NOT(ISNUMBER(I33))),"TBD",G33*I33))) | K33: =IF($M33="No",0,IF($M33<>"Yes","TBD",IF($E33="P1",IF(Inputs!$B$6="","TBD",Inputs!$B$6),IF($E33="P2",IF(Inputs!$B$7="","TBD",Inputs!$B$7),IF($E33="P3",IF(Inputs!$B$8="","TBD",Inputs!$B$8),IF($E33="DEV",IF(Inputs!$B$11="","TBD",Inputs!$B$11),"TBD")))))) | L33: =IF($M33="No",0,IF($M33<>"Yes","TBD",IF(OR(J33="TBD",K33="TBD"),"TBD",J33*K33))) | M33: TBD | N33: [ASSUMPTION] Next-scope decisions; no revenue forecast. Prior planning inputs archived, inactive: quantity=2; hours/unit='=Inputs!$B$12'. [ASSUMPTION, not measured or approved.] Re-enter reviewed values before setting Yes.
A34: 4 | B34: All remaining functionality | C34: F-P2-01 | D34: Partner | E34: P2 | F34: Define operating procedures for expanded network services | H34: working day | J34: =IF($M34="No",0,IF($M34<>"Yes","TBD",IF(OR(NOT(ISNUMBER(G34)),NOT(ISNUMBER(I34))),"TBD",G34*I34))) | K34: =IF($M34="No",0,IF($M34<>"Yes","TBD",IF($E34="P1",IF(Inputs!$B$6="","TBD",Inputs!$B$6),IF($E34="P2",IF(Inputs!$B$7="","TBD",Inputs!$B$7),IF($E34="P3",IF(Inputs!$B$8="","TBD",Inputs!$B$8),IF($E34="DEV",IF(Inputs!$B$11="","TBD",Inputs!$B$11),"TBD")))))) | L34: =IF($M34="No",0,IF($M34<>"Yes","TBD",IF(OR(J34="TBD",K34="TBD"),"TBD",J34*K34))) | M34: TBD | N34: [ASSUMPTION] Service, event and communications procedures after pilot evidence. Prior planning inputs archived, inactive: quantity=5; hours/unit='=Inputs!$B$12'. [ASSUMPTION, not measured or approved.] Re-enter reviewed values before setting Yes.
A35: 4 | B35: All remaining functionality | C35: F-P3-01 | D35: Partner | E35: P3 | F35: Prioritize full-function roadmap and coordinate delivery partners | H35: working day | J35: =IF($M35="No",0,IF($M35<>"Yes","TBD",IF(OR(NOT(ISNUMBER(G35)),NOT(ISNUMBER(I35))),"TBD",G35*I35))) | K35: =IF($M35="No",0,IF($M35<>"Yes","TBD",IF($E35="P1",IF(Inputs!$B$6="","TBD",Inputs!$B$6),IF($E35="P2",IF(Inputs!$B$7="","TBD",Inputs!$B$7),IF($E35="P3",IF(Inputs!$B$8="","TBD",Inputs!$B$8),IF($E35="DEV",IF(Inputs!$B$11="","TBD",Inputs!$B$11),"TBD")))))) | L35: =IF($M35="No",0,IF($M35<>"Yes","TBD",IF(OR(J35="TBD",K35="TBD"),"TBD",J35*K35))) | M35: TBD | N35: [ASSUMPTION] Dependency-aware roadmap and partner coordination. Prior planning inputs archived, inactive: quantity=8; hours/unit='=Inputs!$B$12'. [ASSUMPTION, not measured or approved.] Re-enter reviewed values before setting Yes.
A36: 4 | B36: All remaining functionality | C36: F-DEV-01 | D36: Software | E36: DEV | F36: Build expanded member service workflows | H36: contractor day | J36: =IF($M36="No",0,IF($M36<>"Yes","TBD",IF(OR(NOT(ISNUMBER(G36)),NOT(ISNUMBER(I36))),"TBD",G36*I36))) | K36: =IF($M36="No",0,IF($M36<>"Yes","TBD",IF($E36="P1",IF(Inputs!$B$6="","TBD",Inputs!$B$6),IF($E36="P2",IF(Inputs!$B$7="","TBD",Inputs!$B$7),IF($E36="P3",IF(Inputs!$B$8="","TBD",Inputs!$B$8),IF($E36="DEV",IF(Inputs!$B$11="","TBD",Inputs!$B$11),"TBD")))))) | L36: =IF($M36="No",0,IF($M36<>"Yes","TBD",IF(OR(J36="TBD",K36="TBD"),"TBD",J36*K36))) | M36: TBD | N36: [ASSUMPTION] Initial bounded member-services release. Prior planning inputs archived, inactive: quantity=12; hours/unit='=Inputs!$B$10'. [ASSUMPTION, not measured or approved.] Re-enter reviewed values before setting Yes.
A37: 4 | B37: All remaining functionality | C37: F-DEV-02 | D37: Software | E37: DEV | F37: Build permissioned knowledge repository and reuse workflow | H37: contractor day | J37: =IF($M37="No",0,IF($M37<>"Yes","TBD",IF(OR(NOT(ISNUMBER(G37)),NOT(ISNUMBER(I37))),"TBD",G37*I37))) | K37: =IF($M37="No",0,IF($M37<>"Yes","TBD",IF($E37="P1",IF(Inputs!$B$6="","TBD",Inputs!$B$6),IF($E37="P2",IF(Inputs!$B$7="","TBD",Inputs!$B$7),IF($E37="P3",IF(Inputs!$B$8="","TBD",Inputs!$B$8),IF($E37="DEV",IF(Inputs!$B$11="","TBD",Inputs!$B$11),"TBD")))))) | L37: =IF($M37="No",0,IF($M37<>"Yes","TBD",IF(OR(J37="TBD",K37="TBD"),"TBD",J37*K37))) | M37: TBD | N37: [ASSUMPTION] One permissioned knowledge workflow; migration/licensing excluded. Prior planning inputs archived, inactive: quantity=10; hours/unit='=Inputs!$B$10'. [ASSUMPTION, not measured or approved.] Re-enter reviewed values before setting Yes.
A38: 4 | B38: All remaining functionality | C38: F-DEV-03 | D38: Software | E38: DEV | F38: Build network intelligence and targeted alert functions | H38: contractor day | J38: =IF($M38="No",0,IF($M38<>"Yes","TBD",IF(OR(NOT(ISNUMBER(G38)),NOT(ISNUMBER(I38))),"TBD",G38*I38))) | K38: =IF($M38="No",0,IF($M38<>"Yes","TBD",IF($E38="P1",IF(Inputs!$B$6="","TBD",Inputs!$B$6),IF($E38="P2",IF(Inputs!$B$7="","TBD",Inputs!$B$7),IF($E38="P3",IF(Inputs!$B$8="","TBD",Inputs!$B$8),IF($E38="DEV",IF(Inputs!$B$11="","TBD",Inputs!$B$11),"TBD")))))) | L38: =IF($M38="No",0,IF($M38<>"Yes","TBD",IF(OR(J38="TBD",K38="TBD"),"TBD",J38*K38))) | M38: TBD | N38: [ASSUMPTION] Bounded feed/alert functions; third-party data/message fees excluded. Prior planning inputs archived, inactive: quantity=10; hours/unit='=Inputs!$B$10'. [ASSUMPTION, not measured or approved.] Re-enter reviewed values before setting Yes.
... A40: 4 | B40: All remaining functionality | C40: F-DEV-05 | D40: Software | E40: DEV | F40: Hardening, accessibility checks and full-scope operations handover | H40: contractor day | J40: =IF($M40="No",0,IF($M40<>"Yes","TBD",IF(OR(NOT(ISNUMBER(G40)),NOT(ISNUMBER(I40))),"TBD",G40*I40))) | K40: =IF($M40="No",0,IF($M40<>"Yes","TBD",IF($E40="P1",IF(Inputs!$B$6="","TBD",Inputs!$B$6),IF($E40="P2",IF(Inputs!$B$7="","TBD",Inputs!$B$7),IF($E40="P3",IF(Inputs!$B$8="","TBD",Inputs!$B$8),IF($E40="DEV",IF(Inputs!$B$11="","TBD",Inputs!$B$11),"TBD")))))) | L40: =IF($M40="No",0,IF($M40<>"Yes","TBD",IF(OR(J40="TBD",K40="TBD"),"TBD",J40*K40))) | M40: TBD | N40: [ASSUMPTION] Release hardening/handover; ongoing support and external certification excluded. Prior planning inputs archived, inactive: quantity=10; hours/unit='=Inputs!$B$10'. [ASSUMPTION, not measured or approved.] Re-enter reviewed values before setting Yes.

Sheet Scope Summary
A1: Four commercial scopes · itemized cost model (not pricing tiers)
A2: Each row is an independent incremental scope, not a cumulative offer or low/base/high tier. Select and combine scopes only after written agreement. The graph/search replacement-value line is conditional in Scope 2; it is not an automatic fee.
A4: Scope ID | B4: Commercial scope | C4: Partner hours in scope | D4: Software hours in scope | E4: P1 fee (GBP) | F4: P2 fee (GBP) | G4: P3 fee (GBP) | H4: Software cost (GBP) | I4: Conditional graph/search replacement value (GBP) | J4: External cost (GBP) | K4: Scope subtotal (GBP) | L4: Partner hours through this scope (not price tier) | M4: Cumulative software hours | N4: Cumulative total (GBP) | O4: Scope note | P4: Internal author allocation (from reuse fee; excluded from client total)
A5: 1 | B5: Consulting / strategy | C5: =IF(OR(COUNTIFS('Work Breakdown'!$A$5:$A$40,$A5,'Work Breakdown'!$D$5:$D$40,"Partner",'Work Breakdown'!$M$5:$M$40,"TBD")>0,COUNTIFS('Work Breakdown'!$A$5:$A$40,$A5,'Work Breakdown'!$D$5:$D$40,"Partner",'Work Breakdown'!$M$5:$M$40,"Yes",'Work Breakdown'!$J$5:$J$40,"TBD")>0),"TBD",SUMIFS('Work Breakdown'!$J$5:$J$40,'Work Breakdown'!$A$5:$A$40,$A5,'Work Breakdown'!$D$5:$D$40,"Partner",'Work Breakdown'!$M$5:$M$40,"Yes")) | D5: =IF(OR(COUNTIFS('Work Breakdown'!$A$5:$A$40,$A5,'Work Breakdown'!$D$5:$D$40,"Software",'Work Breakdown'!$M$5:$M$40,"TBD")>0,COUNTIFS('Work Breakdown'!$A$5:$A$40,$A5,'Work Breakdown'!$D$5:$D$40,"Software",'Work Breakdown'!$M$5:$M$40,"Yes",'Work Breakdown'!$J$5:$J$40,"TBD")>0),"TBD",SUMIFS('Work Breakdown'!$J$5:$J$40,'Work Breakdown'!$A$5:$A$40,$A5,'Work Breakdown'!$D$5:$D$40,"Software",'Work Breakdown'!$M$5:$M$40,"Yes")) | E5: =IF(OR(COUNTIFS('Work Breakdown'!$A$5:$A$40,$A5,'Work Breakdown'!$D$5:$D$40,"Partner",'Work Breakdown'!$E$5:$E$40,"P1",'Work Breakdown'!$M$5:$M$40,"TBD")>0,COUNTIFS('Work Breakdown'!$A$5:$A$40,$A5,'Work Breakdown'!$D$5:$D$40,"Partner",'Work Breakdown'!$E$5:$E$40,"P1",'Work Breakdown'!$M$5:$M$40,"Yes",'Work Breakdown'!$L$5:$L$40,"TBD")>0),"TBD",SUMIFS('Work Breakdown'!$L$5:$L$40,'Work Breakdown'!$A$5:$A$40,$A5,'Work Breakdown'!$D$5:$D$40,"Partner",'Work Breakdown'!$E$5:$E$40,"P1",'Work Breakdown'!$M$5:$M$40,"Yes")) | F5: =IF(OR(COUNTIFS('Work Breakdown'!$A$5:$A$40,$A5,'Work Breakdown'!$D$5:$D$40,"Partner",'Work Breakdown'!$E$5:$E$40,"P2",'Work Breakdown'!$M$5:$M$40,"TBD")>0,COUNTIFS('Work Breakdown'!$A$5:$A$40,$A5,'Work Breakdown'!$D$5:$D$40,"Partner",'Work Breakdown'!$E$5:$E$40,"P2",'Work Breakdown'!$M$5:$M$40,"Yes",'Work Breakdown'!$L$5:$L$40,"TBD")>0),"TBD",SUMIFS('Work Breakdown'!$L$5:$L$40,'Work Breakdown'!$A$5:$A$40,$A5,'Work Breakdown'!$D$5:$D$40,"Partner",'Work Breakdown'!$E$5:$E$40,"P2",'Work Breakdown'!$M$5:$M$40,"Yes")) | G5: =IF(OR(COUNTIFS('Work Breakdown'!$A$5:$A$40,$A5,'Work Breakdown'!$D$5:$D$40,"Partner",'Work Breakdown'!$E$5:$E$40,"P3",'Work Breakdown'!$M$5:$M$40,"TBD")>0,COUNTIFS('Work Breakdown'!$A$5:$A$40,$A5,'Work Breakdown'!$D$5:$D$40,"Partner",'Work Breakdown'!$E$5:$E$40,"P3",'Work Breakdown'!$M$5:$M$40,"Yes",'Work Breakdown'!$L$5:$L$40,"TBD")>0),"TBD",SUMIFS('Work Breakdown'!$L$5:$L$40,'Work Breakdown'!$A$5:$A$40,$A5,'Work Breakdown'!$D$5:$D$40,"Partner",'Work Breakdown'!$E$5:$E$40,"P3",'Work Breakdown'!$M$5:$M$40,"Yes")) | H5: =IF(OR(COUNTIFS('Work Breakdown'!$A$5:$A$40,$A5,'Work Breakdown'!$D$5:$D$40,"Software",'Work Breakdown'!$E$5:$E$40,"DEV",'Work Breakdown'!$M$5:$M$40,"TBD")>0,COUNTIFS('Work Breakdown'!$A$5:$A$40,$A5,'Work Breakdown'!$D$5:$D$40,"Software",'Work Breakdown'!$E$5:$E$40,"DEV",'Work Breakdown'!$M$5:$M$40,"Yes",'Work Breakdown'!$L$5:$L$40,"TBD")>0),"TBD",SUMIFS('Work Breakdown'!$L$5:$L$40,'Work Breakdown'!$A$5:$A$40,$A5,'Work Breakdown'!$D$5:$D$40,"Software",'Work Breakdown'!$E$5:$E$40,"DEV",'Work Breakdown'!$M$5:$M$40,"Yes")) | I5: =IF($A5<>2,0,IF(Inputs!$B$32="Include",IF(Inputs!$B$30="","TBD",Inputs!$B$30),IF(Inputs!$B$32="Excluded",0,"TBD"))) | J5: =IF($A5<>4,0,IF(Inputs!$B$20="Include",IF(Inputs!$B$19="","TBD",Inputs!$B$19),IF(Inputs!$B$20="Excluded",0,"TBD"))) | K5: =IF(COUNTIF(E5:J5,"TBD")>0,"TBD",SUM(E5:J5)) | L5: =IF(OR(COUNTIFS('Work Breakdown'!$A$5:$A$40,"<="&$A5,'Work Breakdown'!$D$5:$D$40,"Partner",'Work Breakdown'!$M$5:$M$40,"TBD")>0,COUNTIFS('Work Breakdown'!$A$5:$A$40,"<="&$A5,'Work Breakdown'!$D$5:$D$40,"Partner",'Work Breakdown'!$M$5:$M$40,"Yes",'Work Breakdown'!$J$5:$J$40,"TBD")>0),"TBD",SUMIFS('Work Breakdown'!$J$5:$J$40,'Work Breakdown'!$A$5:$A$40,"<="&$A5,'Work Breakdown'!$D$5:$D$40,"Partner",'Work Breakdown'!$M$5:$M$40,"Yes")) | M5: =SUMIFS('Work Breakdown'!$J$5:$J$40,'Work Breakdown'!$A$5:$A$40,"<="&A5,'Work Breakdown'!$D$5:$D$40,"Software",'Work Breakdown'!$M$5:$M$40,"Yes") | N5: =SUM($K$5:K5) | O5: Consulting only; preparation, facilitation/synthesis and first protocol draft. | P5: =IF(AND(A5=2,Inputs!$B$18="Include"),Inputs!$B$17,0)
A6: 2 | B6: Application MVP | C6: =IF(OR(COUNTIFS('Work Breakdown'!$A$5:$A$40,$A6,'Work Breakdown'!$D$5:$D$40,"Partner",'Work Breakdown'!$M$5:$M$40,"TBD")>0,COUNTIFS('Work Breakdown'!$A$5:$A$40,$A6,'Work Breakdown'!$D$5:$D$40,"Partner",'Work Breakdown'!$M$5:$M$40,"Yes",'Work Breakdown'!$J$5:$J$40,"TBD")>0),"TBD",SUMIFS('Work Breakdown'!$J$5:$J$40,'Work Breakdown'!$A$5:$A$40,$A6,'Work Breakdown'!$D$5:$D$40,"Partner",'Work Breakdown'!$M$5:$M$40,"Yes")) | D6: =IF(OR(COUNTIFS('Work Breakdown'!$A$5:$A$40,$A6,'Work Breakdown'!$D$5:$D$40,"Software",'Work Breakdown'!$M$5:$M$40,"TBD")>0,COUNTIFS('Work Breakdown'!$A$5:$A$40,$A6,'Work Breakdown'!$D$5:$D$40,"Software",'Work Breakdown'!$M$5:$M$40,"Yes",'Work Breakdown'!$J$5:$J$40,"TBD")>0),"TBD",SUMIFS('Work Breakdown'!$J$5:$J$40,'Work Breakdown'!$A$5:$A$40,$A6,'Work Breakdown'!$D$5:$D$40,"Software",'Work Breakdown'!$M$5:$M$40,"Yes")) | E6: =IF(OR(COUNTIFS('Work Breakdown'!$A$5:$A$40,$A6,'Work Breakdown'!$D$5:$D$40,"Partner",'Work Breakdown'!$E$5:$E$40,"P1",'Work Breakdown'!$M$5:$M$40,"TBD")>0,COUNTIFS('Work Breakdown'!$A$5:$A$40,$A6,'Work Breakdown'!$D$5:$D$40,"Partner",'Work Breakdown'!$E$5:$E$40,"P1",'Work Breakdown'!$M$5:$M$40,"Yes",'Work Breakdown'!$L$5:$L$40,"TBD")>0),"TBD",SUMIFS('Work Breakdown'!$L$5:$L$40,'Work Breakdown'!$A$5:$A$40,$A6,'Work Breakdown'!$D$5:$D$40,"Partner",'Work Breakdown'!$E$5:$E$40,"P1",'Work Breakdown'!$M$5:$M$40,"Yes")) | F6: =IF(OR(COUNTIFS('Work Breakdown'!$A$5:$A$40,$A6,'Work Breakdown'!$D$5:$D$40,"Partner",'Work Breakdown'!$E$5:$E$40,"P2",'Work Breakdown'!$M$5:$M$40,"TBD")>0,COUNTIFS('Work Breakdown'!$A$5:$A$40,$A6,'Work Breakdown'!$D$5:$D$40,"Partner",'Work Breakdown'!$E$5:$E$40,"P2",'Work Breakdown'!$M$5:$M$40,"Yes",'Work Breakdown'!$L$5:$L$40,"TBD")>0),"TBD",SUMIFS('Work Breakdown'!$L$5:$L$40,'Work Breakdown'!$A$5:$A$40,$A6,'Work Breakdown'!$D$5:$D$40,"Partner",'Work Breakdown'!$E$5:$E$40,"P2",'Work Breakdown'!$M$5:$M$40,"Yes")) | G6: =IF(OR(COUNTIFS('Work Breakdown'!$A$5:$A$40,$A6,'Work Breakdown'!$D$5:$D$40,"Partner",'Work Breakdown'!$E$5:$E$40,"P3",'Work Breakdown'!$M$5:$M$40,"TBD")>0,COUNTIFS('Work Breakdown'!$A$5:$A$40,$A6,'Work Breakdown'!$D$5:$D$40,"Partner",'Work Breakdown'!$E$5:$E$40,"P3",'Work Breakdown'!$M$5:$M$40,"Yes",'Work Breakdown'!$L$5:$L$40,"TBD")>0),"TBD",SUMIFS('Work Breakdown'!$L$5:$L$40,'Work Breakdown'!$A$5:$A$40,$A6,'Work Breakdown'!$D$5:$D$40,"Partner",'Work Breakdown'!$E$5:$E$40,"P3",'Work Breakdown'!$M$5:$M$40,"Yes")) | H6: =IF(OR(COUNTIFS('Work Breakdown'!$A$5:$A$40,$A6,'Work Breakdown'!$D$5:$D$40,"Software",'Work Breakdown'!$E$5:$E$40,"DEV",'Work Breakdown'!$M$5:$M$40,"TBD")>0,COUNTIFS('Work Breakdown'!$A$5:$A$40,$A6,'Work Breakdown'!$D$5:$D$40,"Software",'Work Breakdown'!$E$5:$E$40,"DEV",'Work Breakdown'!$M$5:$M$40,"Yes",'Work Breakdown'!$L$5:$L$40,"TBD")>0),"TBD",SUMIFS('Work Breakdown'!$L$5:$L$40,'Work Breakdown'!$A$5:$A$40,$A6,'Work Breakdown'!$D$5:$D$40,"Software",'Work Breakdown'!$E$5:$E$40,"DEV",'Work Breakdown'!$M$5:$M$40,"Yes")) | I6: =IF($A6<>2,0,IF(Inputs!$B$32="Include",IF(Inputs!$B$30="","TBD",Inputs!$B$30),IF(Inputs!$B$32="Excluded",0,"TBD"))) | J6: =IF($A6<>4,0,IF(Inputs!$B$20="Include",IF(Inputs!$B$19="","TBD",Inputs!$B$19),IF(Inputs!$B$20="Excluded",0,"TBD"))) | K6: =IF(COUNTIF(E6:J6,"TBD")>0,"TBD",SUM(E6:J6)) | L6: =IF(OR(COUNTIFS('Work Breakdown'!$A$5:$A$40,"<="&$A6,'Work Breakdown'!$D$5:$D$40,"Partner",'Work Breakdown'!$M$5:$M$40,"TBD")>0,COUNTIFS('Work Breakdown'!$A$5:$A$40,"<="&$A6,'Work Breakdown'!$D$5:$D$40,"Partner",'Work Breakdown'!$M$5:$M$40,"Yes",'Work Breakdown'!$J$5:$J$40,"TBD")>0),"TBD",SUMIFS('Work Breakdown'!$J$5:$J$40,'Work Breakdown'!$A$5:$A$40,"<="&$A6,'Work Breakdown'!$D$5:$D$40,"Partner",'Work Breakdown'!$M$5:$M$40,"Yes")) | M6: =SUMIFS('Work Breakdown'!$J$5:$J$40,'Work Breakdown'!$A$5:$A$40,"<="&A6,'Work Breakdown'!$D$5:$D$40,"Software",'Work Breakdown'!$M$5:$M$40,"Yes") | N6: =SUM($K$5:K6) | O6: Adds proposed residual MVP software and partner workflow work to Circle 1. | P6: =IF(AND(A6=2,Inputs!$B$18="Include"),Inputs!$B$17,0)
A7: 3 | B7: Bounded one-client pilot functionality | C7: =IF(OR(COUNTIFS('Work Breakdown'!$A$5:$A$40,$A7,'Work Breakdown'!$D$5:$D$40,"Partner",'Work Breakdown'!$M$5:$M$40,"TBD")>0,COUNTIFS('Work Breakdown'!$A$5:$A$40,$A7,'Work Breakdown'!$D$5:$D$40,"Partner",'Work Breakdown'!$M$5:$M$40,"Yes",'Work Breakdown'!$J$5:$J$40,"TBD")>0),"TBD",SUMIFS('Work Breakdown'!$J$5:$J$40,'Work Breakdown'!$A$5:$A$40,$A7,'Work Breakdown'!$D$5:$D$40,"Partner",'Work Breakdown'!$M$5:$M$40,"Yes")) | D7: =IF(OR(COUNTIFS('Work Breakdown'!$A$5:$A$40,$A7,'Work Breakdown'!$D$5:$D$40,"Software",'Work Breakdown'!$M$5:$M$40,"TBD")>0,COUNTIFS('Work Breakdown'!$A$5:$A$40,$A7,'Work Breakdown'!$D$5:$D$40,"Software",'Work Breakdown'!$M$5:$M$40,"Yes",'Work Breakdown'!$J$5:$J$40,"TBD")>0),"TBD",SUMIFS('Work Breakdown'!$J$5:$J$40,'Work Breakdown'!$A$5:$A$40,$A7,'Work Breakdown'!$D$5:$D$40,"Software",'Work Breakdown'!$M$5:$M$40,"Yes")) | E7: =IF(OR(COUNTIFS('Work Breakdown'!$A$5:$A$40,$A7,'Work Breakdown'!$D$5:$D$40,"Partner",'Work Breakdown'!$E$5:$E$40,"P1",'Work Breakdown'!$M$5:$M$40,"TBD")>0,COUNTIFS('Work Breakdown'!$A$5:$A$40,$A7,'Work Breakdown'!$D$5:$D$40,"Partner",'Work Breakdown'!$E$5:$E$40,"P1",'Work Breakdown'!$M$5:$M$40,"Yes",'Work Breakdown'!$L$5:$L$40,"TBD")>0),"TBD",SUMIFS('Work Breakdown'!$L$5:$L$40,'Work Breakdown'!$A$5:$A$40,$A7,'Work Breakdown'!$D$5:$D$40,"Partner",'Work Breakdown'!$E$5:$E$40,"P1",'Work Breakdown'!$M$5:$M$40,"Yes")) | F7: =IF(OR(COUNTIFS('Work Breakdown'!$A$5:$A$40,$A7,'Work Breakdown'!$D$5:$D$40,"Partner",'Work Breakdown'!$E$5:$E$40,"P2",'Work Breakdown'!$M$5:$M$40,"TBD")>0,COUNTIFS('Work Breakdown'!$A$5:$A$40,$A7,'Work Breakdown'!$D$5:$D$40,"Partner",'Work Breakdown'!$E$5:$E$40,"P2",'Work Breakdown'!$M$5:$M$40,"Yes",'Work Breakdown'!$L$5:$L$40,"TBD")>0),"TBD",SUMIFS('Work Breakdown'!$L$5:$L$40,'Work Breakdown'!$A$5:$A$40,$A7,'Work Breakdown'!$D$5:$D$40,"Partner",'Work Breakdown'!$E$5:$E$40,"P2",'Work Breakdown'!$M$5:$M$40,"Yes")) | G7: =IF(OR(COUNTIFS('Work Breakdown'!$A$5:$A$40,$A7,'Work Breakdown'!$D$5:$D$40,"Partner",'Work Breakdown'!$E$5:$E$40,"P3",'Work Breakdown'!$M$5:$M$40,"TBD")>0,COUNTIFS('Work Breakdown'!$A$5:$A$40,$A7,'Work Breakdown'!$D$5:$D$40,"Partner",'Work Breakdown'!$E$5:$E$40,"P3",'Work Breakdown'!$M$5:$M$40,"Yes",'Work Breakdown'!$L$5:$L$40,"TBD")>0),"TBD",SUMIFS('Work Breakdown'!$L$5:$L$40,'Work Breakdown'!$A$5:$A$40,$A7,'Work Breakdown'!$D$5:$D$40,"Partner",'Work Breakdown'!$E$5:$E$40,"P3",'Work Breakdown'!$M$5:$M$40,"Yes")) | H7: =IF(OR(COUNTIFS('Work Breakdown'!$A$5:$A$40,$A7,'Work Breakdown'!$D$5:$D$40,"Software",'Work Breakdown'!$E$5:$E$40,"DEV",'Work Breakdown'!$M$5:$M$40,"TBD")>0,COUNTIFS('Work Breakdown'!$A$5:$A$40,$A7,'Work Breakdown'!$D$5:$D$40,"Software",'Work Breakdown'!$E$5:$E$40,"DEV",'Work Breakdown'!$M$5:$M$40,"Yes",'Work Breakdown'!$L$5:$L$40,"TBD")>0),"TBD",SUMIFS('Work Breakdown'!$L$5:$L$40,'Work Breakdown'!$A$5:$A$40,$A7,'Work Breakdown'!$D$5:$D$40,"Software",'Work Breakdown'!$E$5:$E$40,"DEV",'Work Breakdown'!$M$5:$M$40,"Yes")) | I7: =IF($A7<>2,0,IF(Inputs!$B$32="Include",IF(Inputs!$B$30="","TBD",Inputs!$B$30),IF(Inputs!$B$32="Excluded",0,"TBD"))) | J7: =IF($A7<>4,0,IF(Inputs!$B$20="Include",IF(Inputs!$B$19="","TBD",Inputs!$B$19),IF(Inputs!$B$20="Excluded",0,"TBD"))) | K7: =IF(COUNTIF(E7:J7,"TBD")>0,"TBD",SUM(E7:J7)) | L7: =IF(OR(COUNTIFS('Work Breakdown'!$A$5:$A$40,"<="&$A7,'Work Breakdown'!$D$5:$D$40,"Partner",'Work Breakdown'!$M$5:$M$40,"TBD")>0,COUNTIFS('Work Breakdown'!$A$5:$A$40,"<="&$A7,'Work Breakdown'!$D$5:$D$40,"Partner",'Work Breakdown'!$M$5:$M$40,"Yes",'Work Breakdown'!$J$5:$J$40,"TBD")>0),"TBD",SUMIFS('Work Breakdown'!$J$5:$J$40,'Work Breakdown'!$A$5:$A$40,"<="&$A7,'Work Breakdown'!$D$5:$D$40,"Partner",'Work Breakdown'!$M$5:$M$40,"Yes")) | M7: =SUMIFS('Work Breakdown'!$J$5:$J$40,'Work Breakdown'!$A$5:$A$40,"<="&A7,'Work Breakdown'!$D$5:$D$40,"Software",'Work Breakdown'!$M$5:$M$40,"Yes") | N7: =SUM($K$5:K7) | O7: Adds pilot outreach, participation and pilot measures. Paid membership/payment processing is excluded and remains a separately scoped post-pilot option. Dossier review capacity is not priced until a permitted sample is measured. | P7: =IF(AND(A7=2,Inputs!$B$18="Include"),Inputs!$B$17,0)
A8: 4 | B8: Other / post-pilot functionality | C8: =IF(OR(COUNTIFS('Work Breakdown'!$A$5:$A$40,$A8,'Work Breakdown'!$D$5:$D$40,"Partner",'Work Breakdown'!$M$5:$M$40,"TBD")>0,COUNTIFS('Work Breakdown'!$A$5:$A$40,$A8,'Work Breakdown'!$D$5:$D$40,"Partner",'Work Breakdown'!$M$5:$M$40,"Yes",'Work Breakdown'!$J$5:$J$40,"TBD")>0),"TBD",SUMIFS('Work Breakdown'!$J$5:$J$40,'Work Breakdown'!$A$5:$A$40,$A8,'Work Breakdown'!$D$5:$D$40,"Partner",'Work Breakdown'!$M$5:$M$40,"Yes")) | D8: =IF(OR(COUNTIFS('Work Breakdown'!$A$5:$A$40,$A8,'Work Breakdown'!$D$5:$D$40,"Software",'Work Breakdown'!$M$5:$M$40,"TBD")>0,COUNTIFS('Work Breakdown'!$A$5:$A$40,$A8,'Work Breakdown'!$D$5:$D$40,"Software",'Work Breakdown'!$M$5:$M$40,"Yes",'Work Breakdown'!$J$5:$J$40,"TBD")>0),"TBD",SUMIFS('Work Breakdown'!$J$5:$J$40,'Work Breakdown'!$A$5:$A$40,$A8,'Work Breakdown'!$D$5:$D$40,"Software",'Work Breakdown'!$M$5:$M$40,"Yes")) | E8: =IF(OR(COUNTIFS('Work Breakdown'!$A$5:$A$40,$A8,'Work Breakdown'!$D$5:$D$40,"Partner",'Work Breakdown'!$E$5:$E$40,"P1",'Work Breakdown'!$M$5:$M$40,"TBD")>0,COUNTIFS('Work Breakdown'!$A$5:$A$40,$A8,'Work Breakdown'!$D$5:$D$40,"Partner",'Work Breakdown'!$E$5:$E$40,"P1",'Work Breakdown'!$M$5:$M$40,"Yes",'Work Breakdown'!$L$5:$L$40,"TBD")>0),"TBD",SUMIFS('Work Breakdown'!$L$5:$L$40,'Work Breakdown'!$A$5:$A$40,$A8,'Work Breakdown'!$D$5:$D$40,"Partner",'Work Breakdown'!$E$5:$E$40,"P1",'Work Breakdown'!$M$5:$M$40,"Yes")) | F8: =IF(OR(COUNTIFS('Work Breakdown'!$A$5:$A$40,$A8,'Work Breakdown'!$D$5:$D$40,"Partner",'Work Breakdown'!$E$5:$E$40,"P2",'Work Breakdown'!$M$5:$M$40,"TBD")>0,COUNTIFS('Work Breakdown'!$A$5:$A$40,$A8,'Work Breakdown'!$D$5:$D$40,"Partner",'Work Breakdown'!$E$5:$E$40,"P2",'Work Breakdown'!$M$5:$M$40,"Yes",'Work Breakdown'!$L$5:$L$40,"TBD")>0),"TBD",SUMIFS('Work Breakdown'!$L$5:$L$40,'Work Breakdown'!$A$5:$A$40,$A8,'Work Breakdown'!$D$5:$D$40,"Partner",'Work Breakdown'!$E$5:$E$40,"P2",'Work Breakdown'!$M$5:$M$40,"Yes")) | G8: =IF(OR(COUNTIFS('Work Breakdown'!$A$5:$A$40,$A8,'Work Breakdown'!$D$5:$D$40,"Partner",'Work Breakdown'!$E$5:$E$40,"P3",'Work Breakdown'!$M$5:$M$40,"TBD")>0,COUNTIFS('Work Breakdown'!$A$5:$A$40,$A8,'Work Breakdown'!$D$5:$D$40,"Partner",'Work Breakdown'!$E$5:$E$40,"P3",'Work Breakdown'!$M$5:$M$40,"Yes",'Work Breakdown'!$L$5:$L$40,"TBD")>0),"TBD",SUMIFS('Work Breakdown'!$L$5:$L$40,'Work Breakdown'!$A$5:$A$40,$A8,'Work Breakdown'!$D$5:$D$40,"Partner",'Work Breakdown'!$E$5:$E$40,"P3",'Work Breakdown'!$M$5:$M$40,"Yes")) | H8: =IF(OR(COUNTIFS('Work Breakdown'!$A$5:$A$40,$A8,'Work Breakdown'!$D$5:$D$40,"Software",'Work Breakdown'!$E$5:$E$40,"DEV",'Work Breakdown'!$M$5:$M$40,"TBD")>0,COUNTIFS('Work Breakdown'!$A$5:$A$40,$A8,'Work Breakdown'!$D$5:$D$40,"Software",'Work Breakdown'!$E$5:$E$40,"DEV",'Work Breakdown'!$M$5:$M$40,"Yes",'Work Breakdown'!$L$5:$L$40,"TBD")>0),"TBD",SUMIFS('Work Breakdown'!$L$5:$L$40,'Work Breakdown'!$A$5:$A$40,$A8,'Work Breakdown'!$D$5:$D$40,"Software",'Work Breakdown'!$E$5:$E$40,"DEV",'Work Breakdown'!$M$5:$M$40,"Yes")) | I8: =IF($A8<>2,0,IF(Inputs!$B$32="Include",IF(Inputs!$B$30="","TBD",Inputs!$B$30),IF(Inputs!$B$32="Excluded",0,"TBD"))) | J8: =IF($A8<>4,0,IF(Inputs!$B$20="Include",IF(Inputs!$B$19="","TBD",Inputs!$B$19),IF(Inputs!$B$20="Excluded",0,"TBD"))) | K8: =IF(COUNTIF(E8:J8,"TBD")>0,"TBD",SUM(E8:J8)) | L8: =IF(OR(COUNTIFS('Work Breakdown'!$A$5:$A$40,"<="&$A8,'Work Breakdown'!$D$5:$D$40,"Partner",'Work Breakdown'!$M$5:$M$40,"TBD")>0,COUNTIFS('Work Breakdown'!$A$5:$A$40,"<="&$A8,'Work Breakdown'!$D$5:$D$40,"Partner",'Work Breakdown'!$M$5:$M$40,"Yes",'Work Breakdown'!$J$5:$J$40,"TBD")>0),"TBD",SUMIFS('Work Breakdown'!$J$5:$J$40,'Work Breakdown'!$A$5:$A$40,"<="&$A8,'Work Breakdown'!$D$5:$D$40,"Partner",'Work Breakdown'!$M$5:$M$40,"Yes")) | M8: =SUMIFS('Work Breakdown'!$J$5:$J$40,'Work Breakdown'!$A$5:$A$40,"<="&A8,'Work Breakdown'!$D$5:$D$40,"Software",'Work Breakdown'!$M$5:$M$40,"Yes") | N8: =SUM($K$5:K8) | O8: Adds future network/service functions to Circles 1–3; separate future scope. | P8: =IF(AND(A8=2,Inputs!$B$18="Include"),Inputs!$B$17,0)
A11: Graph/search replacement-value benchmark is 3/5/7 developer-days × the sourced UK contractor-day median; effort remains [ASSUMPTION]. It is not a measured reuse time, licence valuation, partner fee or approved quote. Include in Scope 2 only after written agreement.
A14: Partner work-fee allocation by scope · not a split of client revenue or profit
A15: Circle | B15: Scope | C15: Partner role | D15: Approved partner hours | E15: Agreed partner rate (GBP/hour) | F15: Calculated partner fee (GBP) | G15: Share of partner-work fees within this scope | H15: Basis / status
A16: 1 | B16: =$B$5 | C16: Client communications & business development | D16: =IF(OR(COUNTIFS('Work Breakdown'!$A$5:$A$40,$A16,'Work Breakdown'!$D$5:$D$40,"Partner",'Work Breakdown'!$E$5:$E$40,"P1",'Work Breakdown'!$M$5:$M$40,"TBD")>0,COUNTIFS('Work Breakdown'!$A$5:$A$40,$A16,'Work Breakdown'!$D$5:$D$40,"Partner",'Work Breakdown'!$E$5:$E$40,"P1",'Work Breakdown'!$M$5:$M$40,"Yes",'Work Breakdown'!$J$5:$J$40,"TBD")>0),"TBD",SUMIFS('Work Breakdown'!$J$5:$J$40,'Work Breakdown'!$A$5:$A$40,$A16,'Work Breakdown'!$E$5:$E$40,"P1",'Work Breakdown'!$M$5:$M$40,"Yes")) | E16: =IF(Inputs!$B$6="","TBD",Inputs!$B$6) | F16: =IF(D16="TBD","TBD",IF(D16=0,0,IF(E16="TBD","TBD",D16*E16))) | G16: =IF(COUNTIF($F$16:$F$18,"TBD")>0,"TBD",IF(SUM($F$16:$F$18)=0,"TBD",F16/SUM($F$16:$F$18))) | H16: Approved role hours × agreed rate; not a client revenue/profit share. Unknown inputs remain TBD.
A17: 1 | B17: =$B$5 | C17: Operations, OSINT, events & external communications | D17: =IF(OR(COUNTIFS('Work Breakdown'!$A$5:$A$40,$A17,'Work Breakdown'!$D$5:$D$40,"Partner",'Work Breakdown'!$E$5:$E$40,"P2",'Work Breakdown'!$M$5:$M$40,"TBD")>0,COUNTIFS('Work Breakdown'!$A$5:$A$40,$A17,'Work Breakdown'!$D$5:$D$40,"Partner",'Work Breakdown'!$E$5:$E$40,"P2",'Work Breakdown'!$M$5:$M$40,"Yes",'Work Breakdown'!$J$5:$J$40,"TBD")>0),"TBD",SUMIFS('Work Breakdown'!$J$5:$J$40,'Work Breakdown'!$A$5:$A$40,$A17,'Work Breakdown'!$E$5:$E$40,"P2",'Work Breakdown'!$M$5:$M$40,"Yes")) | E17: =IF(Inputs!$B$7="","TBD",Inputs!$B$7) | F17: =IF(D17="TBD","TBD",IF(D17=0,0,IF(E17="TBD","TBD",D17*E17))) | G17: =IF(COUNTIF($F$16:$F$18,"TBD")>0,"TBD",IF(SUM($F$16:$F$18)=0,"TBD",F17/SUM($F$16:$F$18))) | H17: Approved role hours × agreed rate; not a client revenue/profit share. Unknown inputs remain TBD.
A18: 1 | B18: =$B$5 | C18: Product Owner, strategy & developer relationships | D18: =IF(OR(COUNTIFS('Work Breakdown'!$A$5:$A$40,$A18,'Work Breakdown'!$D$5:$D$40,"Partner",'Work Breakdown'!$E$5:$E$40,"P3",'Work Breakdown'!$M$5:$M$40,"TBD")>0,COUNTIFS('Work Breakdown'!$A$5:$A$40,$A18,'Work Breakdown'!$D$5:$D$40,"Partner",'Work Breakdown'!$E$5:$E$40,"P3",'Work Breakdown'!$M$5:$M$40,"Yes",'Work Breakdown'!$J$5:$J$40,"TBD")>0),"TBD",SUMIFS('Work Breakdown'!$J$5:$J$40,'Work Breakdown'!$A$5:$A$40,$A18,'Work Breakdown'!$E$5:$E$40,"P3",'Work Breakdown'!$M$5:$M$40,"Yes")) | E18: =IF(Inputs!$B$8="","TBD",Inputs!$B$8) | F18: =IF(D18="TBD","TBD",IF(D18=0,0,IF(E18="TBD","TBD",D18*E18))) | G18: =IF(COUNTIF($F$16:$F$18,"TBD")>0,"TBD",IF(SUM($F$16:$F$18)=0,"TBD",F18/SUM($F$16:$F$18))) | H18: Approved role hours × agreed rate; not a client revenue/profit share. Unknown inputs remain TBD.
A19: 2 | B19: =$B$6 | C19: Client communications & business development | D19: =IF(OR(COUNTIFS('Work Breakdown'!$A$5:$A$40,$A19,'Work Breakdown'!$D$5:$D$40,"Partner",'Work Breakdown'!$E$5:$E$40,"P1",'Work Breakdown'!$M$5:$M$40,"TBD")>0,COUNTIFS('Work Breakdown'!$A$5:$A$40,$A19,'Work Breakdown'!$D$5:$D$40,"Partner",'Work Breakdown'!$E$5:$E$40,"P1",'Work Breakdown'!$M$5:$M$40,"Yes",'Work Breakdown'!$J$5:$J$40,"TBD")>0),"TBD",SUMIFS('Work Breakdown'!$J$5:$J$40,'Work Breakdown'!$A$5:$A$40,$A19,'Work Breakdown'!$E$5:$E$40,"P1",'Work Breakdown'!$M$5:$M$40,"Yes")) | E19: =IF(Inputs!$B$6="","TBD",Inputs!$B$6) | F19: =IF(D19="TBD","TBD",IF(D19=0,0,IF(E19="TBD","TBD",D19*E19))) | G19: =IF(COUNTIF($F$19:$F$21,"TBD")>0,"TBD",IF(SUM($F$19:$F$21)=0,"TBD",F19/SUM($F$19:$F$21))) | H19: Approved role hours × agreed rate; not a client revenue/profit share. Unknown inputs remain TBD.
A20: 2 | B20: =$B$6 | C20: Operations, OSINT, events & external communications | D20: =IF(OR(COUNTIFS('Work Breakdown'!$A$5:$A$40,$A20,'Work Breakdown'!$D$5:$D$40,"Partner",'Work Breakdown'!$E$5:$E$40,"P2",'Work Breakdown'!$M$5:$M$40,"TBD")>0,COUNTIFS('Work Breakdown'!$A$5:$A$40,$A20,'Work Breakdown'!$D$5:$D$40,"Partner",'Work Breakdown'!$E$5:$E$40,"P2",'Work Breakdown'!$M$5:$M$40,"Yes",'Work Breakdown'!$J$5:$J$40,"TBD")>0),"TBD",SUMIFS('Work Breakdown'!$J$5:$J$40,'Work Breakdown'!$A$5:$A$40,$A20,'Work Breakdown'!$E$5:$E$40,"P2",'Work Breakdown'!$M$5:$M$40,"Yes")) | E20: =IF(Inputs!$B$7="","TBD",Inputs!$B$7) | F20: =IF(D20="TBD","TBD",IF(D20=0,0,IF(E20="TBD","TBD",D20*E20))) | G20: =IF(COUNTIF($F$19:$F$21,"TBD")>0,"TBD",IF(SUM($F$19:$F$21)=0,"TBD",F20/SUM($F$19:$F$21))) | H20: Approved role hours × agreed rate; not a client revenue/profit share. Unknown inputs remain TBD.
A21: 2 | B21: =$B$6 | C21: Product Owner, strategy & developer relationships | D21: =IF(OR(COUNTIFS('Work Breakdown'!$A$5:$A$40,$A21,'Work Breakdown'!$D$5:$D$40,"Partner",'Work Breakdown'!$E$5:$E$40,"P3",'Work Breakdown'!$M$5:$M$40,"TBD")>0,COUNTIFS('Work Breakdown'!$A$5:$A$40,$A21,'Work Breakdown'!$D$5:$D$40,"Partner",'Work Breakdown'!$E$5:$E$40,"P3",'Work Breakdown'!$M$5:$M$40,"Yes",'Work Breakdown'!$J$5:$J$40,"TBD")>0),"TBD",SUMIFS('Work Breakdown'!$J$5:$J$40,'Work Breakdown'!$A$5:$A$40,$A21,'Work Breakdown'!$E$5:$E$40,"P3",'Work Breakdown'!$M$5:$M$40,"Yes")) | E21: =IF(Inputs!$B$8="","TBD",Inputs!$B$8) | F21: =IF(D21="TBD","TBD",IF(D21=0,0,IF(E21="TBD","TBD",D21*E21))) | G21: =IF(COUNTIF($F$19:$F$21,"TBD")>0,"TBD",IF(SUM($F$19:$F$21)=0,"TBD",F21/SUM($F$19:$F$21))) | H21: Approved role hours × agreed rate; not a client revenue/profit share. Unknown inputs remain TBD.
A22: 3 | B22: =$B$7 | C22: Client communications & business development | D22: =IF(OR(COUNTIFS('Work Breakdown'!$A$5:$A$40,$A22,'Work Breakdown'!$D$5:$D$40,"Partner",'Work Breakdown'!$E$5:$E$40,"P1",'Work Breakdown'!$M$5:$M$40,"TBD")>0,COUNTIFS('Work Breakdown'!$A$5:$A$40,$A22,'Work Breakdown'!$D$5:$D$40,"Partner",'Work Breakdown'!$E$5:$E$40,"P1",'Work Breakdown'!$M$5:$M$40,"Yes",'Work Breakdown'!$J$5:$J$40,"TBD")>0),"TBD",SUMIFS('Work Breakdown'!$J$5:$J$40,'Work Breakdown'!$A$5:$A$40,$A22,'Work Breakdown'!$E$5:$E$40,"P1",'Work Breakdown'!$M$5:$M$40,"Yes")) | E22: =IF(Inputs!$B$6="","TBD",Inputs!$B$6) | F22: =IF(D22="TBD","TBD",IF(D22=0,0,IF(E22="TBD","TBD",D22*E22))) | G22: =IF(COUNTIF($F$22:$F$24,"TBD")>0,"TBD",IF(SUM($F$22:$F$24)=0,"TBD",F22/SUM($F$22:$F$24))) | H22: Approved role hours × agreed rate; not a client revenue/profit share. Unknown inputs remain TBD.
A23: 3 | B23: =$B$7 | C23: Operations, OSINT, events & external communications | D23: =IF(OR(COUNTIFS('Work Breakdown'!$A$5:$A$40,$A23,'Work Breakdown'!$D$5:$D$40,"Partner",'Work Breakdown'!$E$5:$E$40,"P2",'Work Breakdown'!$M$5:$M$40,"TBD")>0,COUNTIFS('Work Breakdown'!$A$5:$A$40,$A23,'Work Breakdown'!$D$5:$D$40,"Partner",'Work Breakdown'!$E$5:$E$40,"P2",'Work Breakdown'!$M$5:$M$40,"Yes",'Work Breakdown'!$J$5:$J$40,"TBD")>0),"TBD",SUMIFS('Work Breakdown'!$J$5:$J$40,'Work Breakdown'!$A$5:$A$40,$A23,'Work Breakdown'!$E$5:$E$40,"P2",'Work Breakdown'!$M$5:$M$40,"Yes")) | E23: =IF(Inputs!$B$7="","TBD",Inputs!$B$7) | F23: =IF(D23="TBD","TBD",IF(D23=0,0,IF(E23="TBD","TBD",D23*E23))) | G23: =IF(COUNTIF($F$22:$F$24,"TBD")>0,"TBD",IF(SUM($F$22:$F$24)=0,"TBD",F23/SUM($F$22:$F$24))) | H23: Approved role hours × agreed rate; not a client revenue/profit share. Unknown inputs remain TBD.
