Workbook

Sheet Readme
A1: ISRM partner budget model — draft for decision
A3: Purpose | B3: A transparent scope and budget sensitivity model for partner review. It is not a signed offer, quotation, delivery commitment, or verified project registry.
A4: Scope basis | B4: The original 13-package greenfield fixed-core estimate is retained as a historical reference only. It is not the revised-scope estimate and includes no validated reuse credit for the client demo.
A5: Effort status | B5: The original Low/Base/High hours remain historical assumptions for the earlier scope only; they are not current product or pricing tiers. Revised production effort, partner consulting effort, demo-module compensation, external costs and operating costs remain TBD pending scope reconciliation, live measurement, partner decisions and comparable quotes. AI use and API costs are excluded from the committed MVP and require separate approval.
A6: Rate sensitivity | B6: Published Clutch provider-rate bands are multiplied by assumed person-hours only to show sensitivity. This is not a quote, not a national rate ceiling, and not the partner team’s actual rate. The project delivery location/team is not confirmed.
A7: Currency | B7: Client preference is GBP; confirm contract currency with partners/client before budgeting. No FX conversion is performed. The UK contractor comparator is shown in GBP, separately from US/Ukraine provider-company benchmarks in USD.
A8: Allocation | B8: The developer and core-team/admin/relationship/representation bands are independent target ranges. Do not add their upper endpoints to a separate profit share. Profit is only a possible residual after verified costs and remains undecided.
A9: Payment terms | B9: The user-approved proposal constraint is an advance of at least 30% and no more than 3 payments total. Later milestone shares remain blank until agreed.
A10: SaaS | B10: No customer/member data, legal basis, consent, or migration permission is assumed. Alex's ~11,700 LinkedIn group count is user-reported and unverified (screenshot/date not retained); it is not unique reach, an expert count, or a conversion denominator. It supersedes the earlier ~11,000 working approximation for planning only.
A11: Data boundary | B11: Blue inputs on Inputs, Work_Packages and Project_Budget; green formulas; yellow assumptions; orange unresolved gates. Blank means unknown, not zero. Inputs!B30 is the separate demo reuse fee, not added twice. Project_Budget is the project-wide revised-scope model; Budget_Model remains historical.
A12: Using the workbook | B12: Use Inputs for contract currency, partner role rates and periods, plus the agreed whole-project reference amount in B47; Project_Budget for bounded effort/cost inputs, scope decisions, KPI/acceptance and roll-up; Partner_Effort and Revised_Scope remain detailed schedules. Historical Low/Base/High figures are not current offer tiers.
A13: Source limits | B13: The draft Source_Register provides a model-local audit trail. It is not a canonical project registry. The original source files remain unchanged; revised-scope scenario assumptions are documented on Revised_Scope.
A14: Revised scope / scenarios | B14: Revised_Scope documents demo reuse, residual work, strategy/Trust & Influence and 300/400/500 dossier scenarios. Project_Budget rolls up all five tracks and Gate 4A; conditional work stays excluded until selected. Unknown inputs remain TBD.
... A19: Bilingual companion / Двомовний супровід | B19: ISRM_Partner_Decision_Input_Draft.md is the English/Ukrainian review narrative and scope companion. / ISRM_Partner_Decision_Input_Draft.md — двомовний супровідний документ для розгляду scope і партнерських рішень.

Sheet Inputs
A1: Inputs and partner decisions
A3: Input ID | B3: Value | C3: Unit / period | D3: Status | E3: Origin / locator | F3: Notes / calculation use | H3: Cell map for formulas
A4: RATE_UA_LOW | B4: 25 | C4: USD / provider-hour; published band | D4: Source-reported | E4: Clutch Software Development Pricing Guide, updated Sep 2026 | F4: Band endpoint, not a national floor or matched quote. | H4: Actual row addresses (formulas): rates B4:B7; share bands B8:B11; profit ceiling B12; advance B13; max payments B14; operations runway cap B15; currency B16; total budget B17; actual costs B18:B21; approved residual share B22; monthly operations cost B23; SaaS monthly cost B24; selected budget shares B25:B26; payment shares B27:B29; demo-module reuse fee B30. New project-wide rates: Inputs!B33:B39; controls/period inputs: Inputs!B40:B46; see Project_Budget.
A5: RATE_UA_HIGH | B5: 49 | C5: USD / provider-hour; published band | D5: Source-reported | E5: Clutch Software Development Pricing Guide, updated Sep 2026 | F5: Band endpoint, not a national ceiling or matched quote.
A6: RATE_US_LOW | B6: 50 | C6: USD / provider-hour; published band | D6: Source-reported | E6: Clutch Software Development Pricing Guide, updated Sep 2026 | F6: Band endpoint, not a national floor or matched quote.
A7: RATE_US_HIGH | B7: 99 | C7: USD / provider-hour; published band | D7: Source-reported | E7: Clutch Software Development Pricing Guide, updated Sep 2026 | F7: Band endpoint, not a national ceiling or matched quote.
A8: DEV_SHARE_MIN | B8: 0.33 | C8: share of agreed budget | D8: User-stated target; uncontracted | E8: Current conversation | F8: Target band only; actual split remains for partner decision.
A9: DEV_SHARE_MAX | B9: 0.5 | C9: share of agreed budget | D9: User-stated target; uncontracted | E9: Current conversation | F9: Do not combine upper bound with a profit share as if separately additive.
A10: OPS_SHARE_MIN | B10: 0.33 | C10: share of agreed budget | D10: User-stated target; uncontracted | E10: Current conversation | F10: Covers core-team management/administration, relationship work and representation.
A11: OPS_SHARE_MAX | B11: 0.5 | C11: share of agreed budget | D11: User-stated target; uncontracted | E11: Current conversation | F11: Target band only; actual split remains for partner decision.
A12: PROFIT_SHARE_MAX | B12: 0.33 | C12: share of verified positive residual | D12: Unapproved decision; inactive | E12: Current conversation; prior partner decision gate | F12: Discussed ceiling only. No profit distribution or reinvestment rule is adopted.
A13: ADVANCE_MIN | B13: 0.3 | C13: share of agreed contract total | D13: User-approved minimum; uncontracted | E13: Current conversation | F13: Later milestone amounts and trigger criteria remain TBD.
A14: MAX_PAYMENTS | B14: 3 | C14: payments per contract | D14: User-approved maximum; uncontracted | E14: Current conversation | F14: Workbook offers three payment-share slots.
A15: OPS_RUNWAY_MAX | B15: 3 | C15: calendar months after launch | D15: User-stated cap; unapproved funding | E15: Current conversation | F15: Only a possible community-service runway; monthly cost and continuation decision remain unknown.
A16: CONTRACT_CURRENCY | C16: currency code | D16: Decision required | E16: Partner/client contract | F16: Client prefers GBP; confirm contract currency with partners/client before entering the budget. No FX conversion is performed.
A17: CONTRACT_BUDGET | C17: contract currency; one-time | D17: Decision required | E17: Final scope and commercial agreement | F17: Enter only after requirements, scope, and contract currency are approved.
A18: DEV_ACTUAL_COST | C18: contract currency; one-time | D18: Decision required | E18: Developer quotes/contracts | F18: Verified developer cost, not the rate-sensitivity proxy.
A19: CORE_TEAM_ACTUAL_COST | C19: contract currency; one-time | D19: Decision required | E19: Three partner fee agreement | F19: Agreed partner delivery fees, excluding DEMO_MODULE_REUSE_FEE (Inputs!B30) to prevent double-counting.
A20: REP_ACTUAL_COST | C20: contract currency; one-time | D20: Decision required | E20: Receipts/approved budget | F20: Representation and other agreed project outlays.
A21: OTHER_ACTUAL_COST | C21: contract currency; one-time | D21: Decision required | E21: Verified supplier quotes/contracts | F21: Other direct project costs; enter zero only if verified.
A22: APPROVED_RESIDUAL_SHARE | C22: share of verified positive residual | D22: Decision required | E22: Partner agreement | F22: Must not exceed the unapproved 33% discussion ceiling unless partners explicitly revise it.
A23: OPS_MONTHLY_COST | C23: contract currency / month | D23: Decision required | E23: Operating plan after pilot | F23: Used only to calculate an optional runway scenario.
A24: SAAS_MONTHLY_COST | C24: contract currency / month | D24: Decision required | E24: Selected production providers and usage profile | F24: Not included in fixed-core sensitivity.
A25: DEV_SHARE_SELECTED | C25: share of agreed budget | D25: Decision required | E25: Partner budget decision | F25: Optional check against the target band.
A26: OPS_SHARE_SELECTED | C26: share of agreed budget | D26: Decision required | E26: Partner budget decision | F26: Optional check against the target band.
A27: PAYMENT_1_SHARE | C27: share of agreed contract total | D27: Decision required | E27: Final payment schedule | F27: Payment 1 is the advance; must be at least the user-approved minimum.
... A30: GRAPH_SEARCH_REUSE_ALLOCATION | C30: contract currency; one-time internal allocation | D30: Partner decision required | E30: Internal partner allocation for graph/search reuse only if separately agreed. Not a separate client fee; no historical payment or hours inferred. | F30: Proposed internal compensation for the search + group-formation demo module; amount is TBD and is not inferred from market benchmarks. Pay the author after receipt of the first client payment. Do not duplicate in CORE_TEAM_ACTUAL_COST (B19).
A31: Project-wide partner rates and operating-period inputs
A32: Input ID | B32: Value | C32: Unit / period | D32: Status | E32: Origin / locator | F32: Notes / calculation use
A33: RATE_PARTNER_BD | C33: contract currency/person-hour | D33: Partner input required | E33: Partner agreement | F33: Partner 1: business development; no salary comparator substituted.
A34: RATE_PARTNER_OSINT_COMMS_EVENTS | C34: contract currency/person-hour | D34: Partner input required | E34: Partner agreement | F34: Partner 2: OSINT, external communications and event management.
A35: RATE_PARTNER_PRODUCT_OWNER | C35: contract currency/person-hour | D35: Partner input required | E35: Partner agreement | F35: Partner 3: Product Owner and developer coordination.
A36: RATE_SPECIALIST_TRAINER | C36: contract currency/person-hour | D36: Partner input required | E36: Training scope/partner agreement | F36: One-time OSINT/data-management training; max one day; actual effort TBD.
A37: RATE_ANALYST | C37: contract currency/person-hour | D37: Partner input required | E37: Analyst agreement | F37: At least one analyst; hours allocated once across work packages.
A38: RATE_EXTERNAL_REVIEWER | C38: contract currency/person-hour | D38: Decision required | E38: Client/reviewer agreement | F38: Only if external reviewers are paid; neither payment nor unpaid status assumed.
A39: RATE_ASSISTANT_OPTIONAL | C39: contract currency/person-hour | D39: Optional; rate TBD | E39: Partner agreement | F39: Optional assistant; excluded unless selected and effort is supplied.
A40: WORKDAY_HOURS | B40: 8 | C40: hours/working day | D40: [ASSUMPTION] conversion only | E40: Current user direction | F40: Only converts stated 2–3 T&I preparation days for one person.
A41: ANALYST_MIN_COUNT | B41: 1 | C41: people | D41: User-stated requirement | E41: Current user direction | F41: Staffing minimum only; not duration or cost.
A42: TRAINING_MAX_DAYS | B42: 1 | C42: working day | D42: User-stated upper bound | E42: Current user direction | F42: Maximum for one-time OSINT/data-management training; not base hours.
A43: TRAINING_MAX_HOURS | B43: =B40*B42 | C43: hours; conditional cap | D43: Formula from assumption/cap | E43: Inputs!B40 × Inputs!B42 | F43: Upper bound only; not included as base training hours.
...

Sheet Project_Budget
A1: ISRM Expert Network — Project-wide budget and scope gates / ISRM Expert Network — Загальний бюджет і контрольні рішення
A2: Partner review working model only; not a quotation, approved price or delivery commitment. / Робоча модель лише для розгляду партнерами; не котировка, не затверджена ціна й не зобов’язання виконати роботи.
A3: Scope covers Tracks 1–5 and Gate 4A. Historical Budget_Model and Work_Packages remain historical only. / Обсяг охоплює треки 1–5 і ворота 4A. Історичні Budget_Model і Work_Packages не є актуальною оцінкою.
A4: Blank inputs mean unknown, never zero. Totals remain TBD until currency, hours/rates, supplier quotes and scope decisions are resolved. / Порожні входи означають «невідомо», а не нуль. Підсумки залишаються TBD до погодження валюти, годин/ставок, котирувань і рішень щодо обсягу.
A5: Blue = user input; green = formula/link; yellow = assumption; orange = unresolved gate; gray = excluded/reference. Taxes excluded. / Синій = ввід користувача; зелений = формула/посилання; жовтий = припущення; помаранчевий = невирішені ворота; сірий = виключено/довідка. Податки не враховано.
A6: ID / Код | B6: Track/gate / Трек/ворота | C6: Deliverable/cost line / Результат / стаття витрат | D6: Responsible function/source / Відповідальна функція / джерело | E6: Cost basis / База розрахунку | F6: Lower-bound effort input / Ввід: нижня межа | G6: Reference effort input / Ввід: орієнтир | H6: Upper-bound effort input / Ввід: верхня межа | I6: Input unit / Одиниця входу | J6: Rate/quote per unit / Ставка/котирування за одиницю | K6: Lower-bound cost / Вартість: нижня межа | L6: Reference cost / Вартість: орієнтир | M6: Upper-bound cost / Вартість: верхня межа | N6: Budget treatment / Облік у бюджеті | O6: Evidence/formula/open condition / Джерело, формула або відкрита умова | P6: KPI/acceptance measure / KPI або критерій приймання | Q6: KPI target/status / Ціль KPI / статус | R6: Deliverable/cost line (UA) / Результат / стаття витрат (укр.)
A7: TI-01 | B7: Track 1 | C7: Prepare Trust & Influence strategic session | D7: =IF('Partner_Effort'!C6="","",'Partner_Effort'!C6) | E7: Partner hours × rate | F7: =IF('Partner_Effort'!D6="","",'Partner_Effort'!D6) | G7: =IF('Partner_Effort'!E6="","",'Partner_Effort'!E6) | H7: =IF('Partner_Effort'!F6="","",'Partner_Effort'!F6) | I7: person-hours | K7: =IF(OR(Inputs!$B$16="",F7="",J7=""),"TBD",F7*J7) | L7: =IF(OR(Inputs!$B$16="",G7="",J7=""),"TBD",G7*J7) | M7: =IF(OR(Inputs!$B$16="",H7="",J7=""),"TBD",H7*J7) | N7: Mandatory | O7: ='Partner_Effort'!H6 | P7: Session brief, agenda, evidence questions and pre-read reviewed. | Q7: Client/board acceptance; numeric target TBD. | R7: Підготувати стратегічну сесію Trust & Influence
A8: TI-02 | B8: Track 1 | C8: Facilitate Trust & Influence strategic session | D8: =IF('Partner_Effort'!C7="","",'Partner_Effort'!C7) | E8: Partner hours × rate | F8: =IF('Partner_Effort'!D7="","",'Partner_Effort'!D7) | G8: =IF('Partner_Effort'!E7="","",'Partner_Effort'!E7) | H8: =IF('Partner_Effort'!F7="","",'Partner_Effort'!F7) | I8: person-hours | K8: =IF(OR(Inputs!$B$16="",F8="",J8=""),"TBD",F8*J8) | L8: =IF(OR(Inputs!$B$16="",G8="",J8=""),"TBD",G8*J8) | M8: =IF(OR(Inputs!$B$16="",H8="",J8=""),"TBD",H8*J8) | N8: Mandatory | O8: ='Partner_Effort'!H7 | P8: Decisions and design principles approved. | Q8: Client/board acceptance; numeric target TBD. | R8: Провести стратегічну сесію Trust & Influence
A9: TI-03 | B9: Track 1 | C9: Synthesize and document session decisions | D9: =IF('Partner_Effort'!C8="","",'Partner_Effort'!C8) | E9: Partner hours × rate | F9: =IF('Partner_Effort'!D8="","",'Partner_Effort'!D8) | G9: =IF('Partner_Effort'!E8="","",'Partner_Effort'!E8) | H9: =IF('Partner_Effort'!F8="","",'Partner_Effort'!F8) | I9: person-hours | K9: =IF(OR(Inputs!$B$16="",F9="",J9=""),"TBD",F9*J9) | L9: =IF(OR(Inputs!$B$16="",G9="",J9=""),"TBD",G9*J9) | M9: =IF(OR(Inputs!$B$16="",H9="",J9=""),"TBD",H9*J9) | N9: Mandatory | O9: ='Partner_Effort'!H8 | P9: Decision log and owners reviewed. | Q9: Client/board acceptance; numeric target TBD. | R9: Узагальнити й задокументувати рішення сесії
A10: TI-04 | B10: Track 1 | C10: Co-design Trust & Influence index/model | D10: =IF('Partner_Effort'!C9="","",'Partner_Effort'!C9) | E10: Partner hours × rate | F10: =IF('Partner_Effort'!D9="","",'Partner_Effort'!D9) | G10: =IF('Partner_Effort'!E9="","",'Partner_Effort'!E9) | H10: =IF('Partner_Effort'!F9="","",'Partner_Effort'!F9) | I10: person-hours | K10: =IF(OR(Inputs!$B$16="",F10="",J10=""),"TBD",F10*J10) | L10: =IF(OR(Inputs!$B$16="",G10="",J10=""),"TBD",G10*J10) | M10: =IF(OR(Inputs!$B$16="",H10="",J10=""),"TBD",H10*J10) | N10: Mandatory | O10: ='Partner_Effort'!H9 | P10: Versioned model and limits approved. | Q10: Client/board acceptance; numeric target TBD. | R10: Спільно розробити індекс / модель Trust & Influence
A11: TI-05 | B11: Track 1 | C11: Draft assessment protocol and correction/appeal path | D11: =IF('Partner_Effort'!C10="","",'Partner_Effort'!C10) | E11: Partner hours × rate | F11: =IF('Partner_Effort'!D10="","",'Partner_Effort'!D10) | G11: =IF('Partner_Effort'!E10="","",'Partner_Effort'!E10) | H11: =IF('Partner_Effort'!F10="","",'Partner_Effort'!F10) | I11: person-hours | K11: =IF(OR(Inputs!$B$16="",F11="",J11=""),"TBD",F11*J11) | L11: =IF(OR(Inputs!$B$16="",G11="",J11=""),"TBD",G11*J11) | M11: =IF(OR(Inputs!$B$16="",H11="",J11=""),"TBD",H11*J11) | N11: Mandatory | O11: ='Partner_Effort'!H10 | P11: Repeatable protocol and audit/correction rules approved. | Q11: Client/board acceptance; numeric target TBD. | R11: Підготувати протокол оцінювання та порядок виправлення / оскарження
A12: TI-06 | B12: Track 1 | C12: Select practice leaders and regional representatives | D12: =IF('Partner_Effort'!C11="","",'Partner_Effort'!C11) | E12: Partner hours × rate | F12: =IF('Partner_Effort'!D11="","",'Partner_Effort'!D11) | G12: =IF('Partner_Effort'!E11="","",'Partner_Effort'!E11) | H12: =IF('Partner_Effort'!F11="","",'Partner_Effort'!F11) | I12: person-hours | K12: =IF(OR(Inputs!$B$16="",F12="",J12=""),"TBD",F12*J12) | L12: =IF(OR(Inputs!$B$16="",G12="",J12=""),"TBD",G12*J12) | M12: =IF(OR(Inputs!$B$16="",H12="",J12=""),"TBD",H12*J12) | N12: Mandatory | O12: ='Partner_Effort'!H11 | P12: Approved reviewer roster. | Q12: Client/board acceptance; numeric target TBD. | R12: Відібрати керівників практик і регіональних представників
A13: TI-07 | B13: Track 1 | C13: Prepare reviewer-group orientation/materials | D13: =IF('Partner_Effort'!C12="","",'Partner_Effort'!C12) | E13: Partner hours × rate | F13: =IF('Partner_Effort'!D12="","",'Partner_Effort'!D12) | G13: =IF('Partner_Effort'!E12="","",'Partner_Effort'!E12) | H13: =IF('Partner_Effort'!F12="","",'Partner_Effort'!F12) | I13: person-hours | K13: =IF(OR(Inputs!$B$16="",F13="",J13=""),"TBD",F13*J13) | L13: =IF(OR(Inputs!$B$16="",G13="",J13=""),"TBD",G13*J13) | M13: =IF(OR(Inputs!$B$16="",H13="",J13=""),"TBD",H13*J13) | N13: Mandatory | O13: ='Partner_Effort'!H12 | P13: Materials map to approved model/protocol. | Q13: Client/board acceptance; numeric target TBD. | R13: Підготувати матеріали для орієнтації групи рецензентів
A14: TI-08 | B14: Track 1 | C14: Deliver reviewer-group orientation/training | D14: =IF('Partner_Effort'!C13="","",'Partner_Effort'!C13) | E14: Partner hours × rate | F14: =IF('Partner_Effort'!D13="","",'Partner_Effort'!D13) | G14: =IF('Partner_Effort'!E13="","",'Partner_Effort'!E13) | H14: =IF('Partner_Effort'!F13="","",'Partner_Effort'!F13) | I14: person-hours | K14: =IF(OR(Inputs!$B$16="",F14="",J14=""),"TBD",F14*J14) | L14: =IF(OR(Inputs!$B$16="",G14="",J14=""),"TBD",G14*J14) | M14: =IF(OR(Inputs!$B$16="",H14="",J14=""),"TBD",H14*J14) | N14: Mandatory | O14: ='Partner_Effort'!H13 | P14: Attendance recorded; not proof of sector-wide validity. | Q14: Client/board acceptance; numeric target TBD. | R14: Провести орієнтацію / навчання групи рецензентів
A15: TI-09 | B15: Track 3 | C15: Apply model/protocol to expert reviews and adjudicate exceptions | D15: =IF('Partner_Effort'!C14="","",'Partner_Effort'!C14) | E15: Partner hours × rate | F15: =IF('Partner_Effort'!D14="","",'Partner_Effort'!D14) | G15: =IF('Partner_Effort'!E14="","",'Partner_Effort'!E14) | H15: =IF('Partner_Effort'!F14="","",'Partner_Effort'!F14) | I15: person-hours | K15: =IF(OR(Inputs!$B$16="",F15="",J15=""),"TBD",F15*J15) | L15: =IF(OR(Inputs!$B$16="",G15="",J15=""),"TBD",G15*J15) | M15: =IF(OR(Inputs!$B$16="",H15="",J15=""),"TBD",H15*J15) | N15: Mandatory | O15: ='Partner_Effort'!H14 | P15: Human review and exceptions logged. | Q15: Client/board acceptance; numeric target TBD. | R15: Застосувати модель / протокол до перевірок експертів і розглянути винятки
A16: STR-01 | B16: Track 1 | C16: Prepare/facilitate additional client strategy sessions | D16: =IF('Partner_Effort'!C15="","",'Partner_Effort'!C15) | E16: Partner hours × rate | F16: =IF('Partner_Effort'!D15="","",'Partner_Effort'!D15) | G16: =IF('Partner_Effort'!E15="","",'Partner_Effort'!E15) | H16: =IF('Partner_Effort'!F15="","",'Partner_Effort'!F15) | I16: person-hours | K16: =IF(OR(Inputs!$B$16="",F16="",J16=""),"TBD",F16*J16) | L16: =IF(OR(Inputs!$B$16="",G16="",J16=""),"TBD",G16*J16) | M16: =IF(OR(Inputs!$B$16="",H16="",J16=""),"TBD",H16*J16) | N16: Mandatory | O16: ='Partner_Effort'!H15 | P16: Priorities, decisions and owners documented. | Q16: Client/board acceptance; numeric target TBD. | R16: Підготувати / провести додаткові стратегічні сесії з клієнтом
A17: STR-02 | B17: Track 1 | C17: Prioritize development directions and expertise gaps | D17: =IF('Partner_Effort'!C16="","",'Partner_Effort'!C16) | E17: Partner hours × rate | F17: =IF('Partner_Effort'!D16="","",'Partner_Effort'!D16) | G17: =IF('Partner_Effort'!E16="","",'Partner_Effort'!E16) | H17: =IF('Partner_Effort'!F16="","",'Partner_Effort'!F16) | I17: person-hours | K17: =IF(OR(Inputs!$B$16="",F17="",J17=""),"TBD",F17*J17) | L17: =IF(OR(Inputs!$B$16="",G17="",J17=""),"TBD",G17*J17) | M17: =IF(OR(Inputs!$B$16="",H17="",J17=""),"TBD",H17*J17) | N17: Mandatory | O17: ='Partner_Effort'!H16 | P17: Priorities have rationale and client decision. | Q17: Client/board acceptance; numeric target TBD. | R17: Визначити пріоритети розвитку та прогалини в експертизі
A18: STR-03 | B18: Track 1 | C18: Set criteria/process to review existing network experts | D18: =IF('Partner_Effort'!C17="","",'Partner_Effort'!C17) | E18: Partner hours × rate | F18: =IF('Partner_Effort'!D17="","",'Partner_Effort'!D17) | G18: =IF('Partner_Effort'!E17="","",'Partner_Effort'!E17) | H18: =IF('Partner_Effort'!F17="","",'Partner_Effort'!F17) | I18: person-hours | K18: =IF(OR(Inputs!$B$16="",F18="",J18=""),"TBD",F18*J18) | L18: =IF(OR(Inputs!$B$16="",G18="",J18=""),"TBD",G18*J18) | M18: =IF(OR(Inputs!$B$16="",H18="",J18=""),"TBD",H18*J18) | N18: Mandatory | O18: ='Partner_Effort'!H17 | P18: Review plan and consent/evidence boundaries approved. | Q18: Client/board acceptance; numeric target TBD. | R18: Визначити критерії та процес перевірки наявних експертів мережі
A19: STR-04 | B19: Track 4 | C19: Prepare community questionnaire/campaign materials | D19: =IF('Partner_Effort'!C18="","",'Partner_Effort'!C18) | E19: Partner hours × rate | F19: =IF('Partner_Effort'!D18="","",'Partner_Effort'!D18) | G19: =IF('Partner_Effort'!E18="","",'Partner_Effort'!E18) | H19: =IF('Partner_Effort'!F18="","",'Partner_Effort'!F18) | I19: person-hours | J19: =IF(Inputs!$B$34="","",Inputs!$B$34) | K19: =IF(OR(Inputs!$B$16="",F19="",J19=""),"TBD",F19*J19) | L19: =IF(OR(Inputs!$B$16="",G19="",J19=""),"TBD",G19*J19) | M19: =IF(OR(Inputs!$B$16="",H19="",J19=""),"TBD",H19*J19) | N19: Mandatory | O19: ='Partner_Effort'!H18 | P19: Approved survey and outreach pack. | Q19: Client/board acceptance; numeric target TBD. | R19: Підготувати опитувальник спільноти й матеріали кампанії
A20: STR-05 | B20: Track 4 | C20: Coordinate and operate approved outreach/survey campaign | D20: =IF('Partner_Effort'!C19="","",'Partner_Effort'!C19) | E20: Partner hours × rate | F20: =IF('Partner_Effort'!D19="","",'Partner_Effort'!D19) | G20: =IF('Partner_Effort'!E19="","",'Partner_Effort'!E19) | H20: =IF('Partner_Effort'!F19="","",'Partner_Effort'!F19) | I20: person-hours | J20: =IF(Inputs!$B$34="","",Inputs!$B$34) | K20: =IF(OR(Inputs!$B$16="",F20="",J20=""),"TBD",F20*J20) | L20: =IF(OR(Inputs!$B$16="",G20="",J20=""),"TBD",G20*J20) | M20: =IF(OR(Inputs!$B$16="",H20="",J20=""),"TBD",H20*J20) | N20: Mandatory | O20: ='Partner_Effort'!H19 | P20: Authorized-channel log and observed results. | Q20: Client/board acceptance; numeric target TBD. | R20: Координувати й провести погоджену кампанію залучення / опитування
A21: STR-06 | B21: Track 4 | C21: Analyze responses and prepare client/board findings | D21: =IF('Partner_Effort'!C20="","",'Partner_Effort'!C20) | E21: Partner hours × rate | F21: =IF('Partner_Effort'!D20="","",'Partner_Effort'!D20) | G21: =IF('Partner_Effort'!E20="","",'Partner_Effort'!E20) | H21: =IF('Partner_Effort'!F20="","",'Partner_Effort'!F20) | I21: person-hours | J21: =IF(Inputs!$B$37="","",Inputs!$B$37) | K21: =IF(OR(Inputs!$B$16="",F21="",J21=""),"TBD",F21*J21) | L21: =IF(OR(Inputs!$B$16="",G21="",J21=""),"TBD",G21*J21) | M21: =IF(OR(Inputs!$B$16="",H21="",J21=""),"TBD",H21*J21) | N21: Mandatory | O21: ='Partner_Effort'!H20 | P21: Observed associations distinguished from causation. | Q21: Client/board acceptance; numeric target TBD. | R21: Проаналізувати відповіді та підготувати висновки для клієнта / ради
A22: OPS-01 | B22: Cross-track | C22: Client support and decision coordination | D22: =IF('Partner_Effort'!C21="","",'Partner_Effort'!C21) | E22: Partner hours × rate | F22: =IF('Partner_Effort'!D21="","",'Partner_Effort'!D21) | G22: =IF('Partner_Effort'!E21="","",'Partner_Effort'!E21) | H22: =IF('Partner_Effort'!F21="","",'Partner_Effort'!F21) | I22: person-hours | J22: =IF(Inputs!$B$33="","",Inputs!$B$33) | K22: =IF(OR(Inputs!$B$16="",F22="",J22=""),"TBD",F22*J22) | L22: =IF(OR(Inputs!$B$16="",G22="",J22=""),"TBD",G22*J22) | M22: =IF(OR(Inputs!$B$16="",H22="",J22=""),"TBD",H22*J22) | N22: Mandatory | O22: ='Partner_Effort'!H21 | P22: Decision, approval, risk/change log maintained. | Q22: Client/board acceptance; numeric target TBD. | R22: Підтримка клієнта й координація рішень
A23: OPS-02 | B23: Track 4 | C23: Pilot operational coordination; dossier minutes excluded until measured | D23: =IF('Partner_Effort'!C22="","",'Partner_Effort'!C22) | E23: Partner hours × rate | F23: =IF('Partner_Effort'!D22="","",'Partner_Effort'!D22) | G23: =IF('Partner_Effort'!E22="","",'Partner_Effort'!E22) | H23: =IF('Partner_Effort'!F22="","",'Partner_Effort'!F22) | I23: person-hours | J23: =IF(Inputs!$B$34="","",Inputs!$B$34) | K23: =IF(OR(Inputs!$B$16="",F23="",J23=""),"TBD",F23*J23) | L23: =IF(OR(Inputs!$B$16="",G23="",J23=""),"TBD",G23*J23) | M23: =IF(OR(Inputs!$B$16="",H23="",J23=""),"TBD",H23*J23) | N23: Mandatory | O23: ='Partner_Effort'!H22 | P23: Pilot hand-offs/exceptions logged. | Q23: Client/board acceptance; numeric target TBD. | R23: Операційна координація пілота; хвилини роботи з досьє виключено до вимірювання
A24: OPS-03 | B24: Track 2 | C24: Developer coordination, scope and acceptance | D24: =IF('Partner_Effort'!C23="","",'Partner_Effort'!C23) | E24: Partner hours × rate | F24: =IF('Partner_Effort'!D23="","",'Partner_Effort'!D23) | G24: =IF('Partner_Effort'!E23="","",'Partner_Effort'!E23) | H24: =IF('Partner_Effort'!F23="","",'Partner_Effort'!F23) | I24: person-hours | J24: =IF(Inputs!$B$35="","",Inputs!$B$35) | K24: =IF(OR(Inputs!$B$16="",F24="",J24=""),"TBD",F24*J24) | L24: =IF(OR(Inputs!$B$16="",G24="",J24=""),"TBD",G24*J24) | M24: =IF(OR(Inputs!$B$16="",H24="",J24=""),"TBD",H24*J24) | N24: Mandatory | O24: ='Partner_Effort'!H23 | P24: Requirements/acceptance trace to scope. | Q24: Client/board acceptance; numeric target TBD. | R24: Координація розробників, обсягу робіт і критеріїв приймання
A25: TRN-01 | B25: Track 1 | C25: One-time OSINT/data-management training | D25: Specialist trainer | E25: hourly | I25: person-hours | J25: =IF(Inputs!$B$36="","",Inputs!$B$36) | K25: =IF(OR(Inputs!$B$16="",F25="",J25=""),"TBD",F25*J25) | L25: =IF(OR(Inputs!$B$16="",G25="",J25=""),"TBD",G25*J25) | M25: =IF(OR(Inputs!$B$16="",H25="",J25=""),"TBD",H25*J25) | N25: Mandatory | O25: Max one working day; actual duration, attendees and prep TBD; cap is not base hours. | P25: Training objectives and completion recorded. | Q25: Numeric target TBD unless approved. | R25: Одноразове навчання з OSINT та управління даними
A26: T3-AN-01 | B26: Track 3 | C26: Analyst: data governance, research and knowledge-base work | D26: At least one analyst | E26: hourly | I26: person-hours | J26: =IF(Inputs!$B$37="","",Inputs!$B$37) | K26: =IF(OR(Inputs!$B$16="",F26="",J26=""),"TBD",F26*J26) | L26: =IF(OR(Inputs!$B$16="",G26="",J26=""),"TBD",G26*J26) | M26: =IF(OR(Inputs!$B$16="",H26="",J26=""),"TBD",H26*J26) | N26: Mandatory | O26: Hours TBD; allocate once across packages, without double-counting. | P26: Source-attributed data/knowledge output accepted. | Q26: Numeric target TBD unless approved. | R26: Аналітик: управління даними, дослідження та робота з базою знань
A27: SW-01 | B27: Track 2 | C27: Residual application implementation, QA, security and deployment | D27: Developer/vendor | E27: quote | I27: contract currency/project | K27: =IF(OR(Inputs!$B$16="",F27=""),"TBD",F27) | L27: =IF(OR(Inputs!$B$16="",G27=""),"TBD",G27) | M27: =IF(OR(Inputs!$B$16="",H27=""),"TBD",H27) | N27: Mandatory | O27: Quote after demo, residual scope, acceptance, data access, IP and support are reconciled; no historical greenfield estimate. | P27: Agreed workflows pass UAT/security/QA. | Q27: Numeric target TBD unless approved. | R27: Залишкова розробка застосунку, QA, безпека й розгортання
A28: DATA-01 | B28: Track 3 | C28: Data model, analytics, dashboard and knowledge-base integration | D28: Developer/data vendor | E28: quote | I28: contract currency/project | K28: =IF(OR(Inputs!$B$16="",F28=""),"TBD",F28) | L28: =IF(OR(Inputs!$B$16="",G28=""),"TBD",G28) | M28: =IF(OR(Inputs!$B$16="",H28=""),"TBD",H28) | N28: Mandatory | O28: Quote after data rights, provenance, owners, metrics and refresh rules are agreed. | P28: Lineage/access/refresh rules and outputs accepted. | Q28: Numeric target TBD unless approved. | R28: Модель даних, аналітика, панель і інтеграція бази знань
A29: COMM-EXT | B29: Track 4 | C29: Campaign, survey, publication, translation and event direct expenses | D29: External suppliers | E29: quote | I29: contract currency/project | K29: =IF(OR(Inputs!$B$16="",F29=""),"TBD",F29) | L29: =IF(OR(Inputs!$B$16="",G29=""),"TBD",G29) | M29: =IF(OR(Inputs!$B$16="",H29=""),"TBD",H29) | N29: Mandatory | O29: Quote/verified cost required; no audience or fee assumed. | P29: Approved assets/events delivered; channel results recorded. | Q29: Numeric target TBD unless approved. | R29: Прямі витрати кампанії, опитування, публікації, перекладу й заходів
A30: DOS-PREP | B30: Dossier pilot | C30: Human preparation per dossier | D30: Analyst/operator | E30: dossier-hour | F30: =IF('Revised_Scope'!C27="TBD","",'Revised_Scope'!C27) | G30: =IF('Revised_Scope'!C28="TBD","",'Revised_Scope'!C28) | H30: =IF('Revised_Scope'!C29="TBD","",'Revised_Scope'!C29) | I30: person-hours | J30: =IF(Inputs!$B$37="","",Inputs!$B$37) | K30: =IF(OR(Inputs!$B$16="",F30="",J30=""),"TBD",F30*J30) | L30: =IF(OR(Inputs!$B$16="",G30="",J30=""),"TBD",G30*J30) | M30: =IF(OR(Inputs!$B$16="",H30="",J30=""),"TBD",H30*J30) | N30: Decision required | O30: Hours link to Revised_Scope; possible volume only; measure in approved live pilot. | P30: Observed minutes per dossier; target TBD. | Q30: Numeric target TBD unless approved. | R30: Людська підготовка одного досьє
A31: DOS-VERIFY | B31: Dossier pilot | C31: Human evidence review/verification | D31: Selected reviewer(s) | E31: dossier-hour | F31: =IF('Revised_Scope'!D27="TBD","",'Revised_Scope'!D27) | G31: =IF('Revised_Scope'!D28="TBD","",'Revised_Scope'!D28) | H31: =IF('Revised_Scope'!D29="TBD","",'Revised_Scope'!D29) | I31: person-hours | J31: =IF(Inputs!$B$38="","",Inputs!$B$38) | K31: =IF(OR(Inputs!$B$16="",F31="",J31=""),"TBD",F31*J31) | L31: =IF(OR(Inputs!$B$16="",G31="",J31=""),"TBD",G31*J31) | M31: =IF(OR(Inputs!$B$16="",H31="",J31=""),"TBD",H31*J31) | N31: Decision required | O31: Time linked from Revised_Scope; payment status unmeasured. | P31: Review traceability; threshold to be agreed. | Q31: Numeric target TBD unless approved. | R31: Людський перегляд / перевірка доказів
A32: DOS-REWORK | B32: Dossier pilot | C32: Correction, appeal and rework | D32: Reviewer/operator | E32: dossier-hour | F32: =IF('Revised_Scope'!E27="TBD","",'Revised_Scope'!E27) | G32: =IF('Revised_Scope'!E28="TBD","",'Revised_Scope'!E28) | H32: =IF('Revised_Scope'!E29="TBD","",'Revised_Scope'!E29) | I32: person-hours | J32: =IF(Inputs!$B$38="","",Inputs!$B$38) | K32: =IF(OR(Inputs!$B$16="",F32="",J32=""),"TBD",F32*J32) | L32: =IF(OR(Inputs!$B$16="",G32="",J32=""),"TBD",G32*J32) | M32: =IF(OR(Inputs!$B$16="",H32="",J32=""),"TBD",H32*J32) | N32: Decision required | O32: Measured only; no exception/rework rate assumed. | P32: Observed minutes and cases reported. | Q32: Numeric target TBD unless approved. | R32: Виправлення, оскарження та повторна робота
A33: DOS-CLIENT | B33: Dossier pilot | C33: Client decision/approval effort | D33: Client-side approver | E33: dossier-client | F33: =IF('Revised_Scope'!F27="TBD","",'Revised_Scope'!F27) | G33: =IF('Revised_Scope'!F28="TBD","",'Revised_Scope'!F28) | H33: =IF('Revised_Scope'!F29="TBD","",'Revised_Scope'!F29) | I33: person-hours | K33: Not priced — client-side effort | L33: Not priced — client-side effort | M33: Not priced — client-side effort | N33: Client-side effort | O33: Client hours shown separately and excluded from supplier price; batch/per-dossier allocation TBD. | P33: Client approval effort measured separately. | Q33: Numeric target TBD unless approved. | R33: Час клієнта на ухвалення / погодження рішень
A34: DOS-API | B34: Dossier pilot | C34: AI provider/API usage for dossier preparation | D34: Selected provider | E34: dossier-api | F34: =IF('Revised_Scope'!I27="TBD","",'Revised_Scope'!I27) | G34: =IF('Revised_Scope'!I28="TBD","",'Revised_Scope'!I28) | H34: =IF('Revised_Scope'!I29="TBD","",'Revised_Scope'!I29) | I34: contract currency/scenario | K34: =IF(OR(Inputs!$B$16="",F34=""),"TBD",F34) | L34: =IF(OR(Inputs!$B$16="",G34=""),"TBD",G34) | M34: =IF(OR(Inputs!$B$16="",H34=""),"TBD",H34) | N34: Decision required | O34: Linked to Revised_Scope; provider/model/profile unselected. | P34: Metered cost per dossier; no cost assumed. | Q34: Numeric target TBD unless approved. | R34: Використання AI-провайдера / API для підготовки досьє
A35: GATE-4A | B35: Track 4A | C35: Pilot evaluation and written continuation decision | D35: Partners/client/evaluator | E35: quote | I35: contract currency/project | K35: =IF(OR(Inputs!$B$16="",F35=""),"TBD",F35) | L35: =IF(OR(Inputs!$B$16="",G35=""),"TBD",G35) | M35: =IF(OR(Inputs!$B$16="",H35=""),"TBD",H35) | N35: Decision required | O35: Go/no-go scope and evaluation design not selected. | P35: Written stop/continue decision against agreed criteria. | Q35: Numeric target TBD unless approved. | R35: Оцінка пілота й письмове рішення про продовження
A36: T5-BUILD | B36: Track 5 | C36: Conditional AI/OSINT/chatbot implementation/integration | D36: Developer/vendor | E36: quote | I36: contract currency/project | K36: =IF(OR(Inputs!$B$16="",F36=""),"TBD",F36) | L36: =IF(OR(Inputs!$B$16="",G36=""),"TBD",G36) | M36: =IF(OR(Inputs!$B$16="",H36=""),"TBD",H36) | N36: Decision required | O36: Only after Gate 4A approval and data rights/readiness. | P36: Agreed citations, audit, human review and rollback tested. | Q36: Numeric target TBD unless approved. | R36: Умовна розробка / інтеграція AI, OSINT або чатбота
A37: T5-USAGE | B37: Track 5 | C37: Conditional model/API/OSINT usage | D37: Selected provider(s) | E37: quote | I37: contract currency/project-period | K37: =IF(OR(Inputs!$B$16="",F37=""),"TBD",F37) | L37: =IF(OR(Inputs!$B$16="",G37=""),"TBD",G37) | M37: =IF(OR(Inputs!$B$16="",H37=""),"TBD",H37) | N37: Decision required | O37: Provider, duration and workload profile not selected. | P37: Usage/cost against approved ceiling; ceiling TBD. | Q37: Numeric target TBD unless approved. | R37: Умовне використання моделей / API / OSINT
A38: LEGAL-01 | B38: Cross-track | C38: Privacy, legal, security and data-rights review | D38: Qualified reviewer | E38: quote | I38: contract currency/project | K38: =IF(OR(Inputs!$B$16="",F38=""),"TBD",F38) | L38: =IF(OR(Inputs!$B$16="",G38=""),"TBD",G38) | M38: =IF(OR(Inputs!$B$16="",H38=""),"TBD",H38) | N38: Mandatory | O38: Scope depends on lawful basis, data access, jurisdiction and providers. | P38: Review completed and control actions tracked. | Q38: Numeric target TBD unless approved. | R38: Перевірка приватності, права, безпеки й прав на дані
A39: OPS-RUN | B39: Post-launch | C39: Post-launch operations/support for agreed period | D39: Service team | E39: monthly | F39: =IF(Inputs!$B$45="","",Inputs!$B$45) | G39: =IF(Inputs!$B$45="","",Inputs!$B$45) | H39: =IF(Inputs!$B$45="","",Inputs!$B$45) | I39: months | J39: =IF(Inputs!$B$23="","",Inputs!$B$23) | K39: =IF(OR(Inputs!$B$16="",F39="",J39=""),"TBD",F39*J39) | L39: =IF(OR(Inputs!$B$16="",G39="",J39=""),"TBD",G39*J39) | M39: =IF(OR(Inputs!$B$16="",H39="",J39=""),"TBD",H39*J39) | N39: Decision required | O39: Inputs!B23 monthly rate × Inputs!B45 duration; no default period. | P39: Service levels agreed. | Q39: Numeric target TBD unless approved. | R39: Операції / підтримка після запуску за погоджений період
A40: SAAS-RUN | B40: Post-launch | C40: Hosting, licences and recurring SaaS | D40: Selected providers | E40: monthly | F40: =IF(Inputs!$B$46="","",Inputs!$B$46) | G40: =IF(Inputs!$B$46="","",Inputs!$B$46) | H40: =IF(Inputs!$B$46="","",Inputs!$B$46) | I40: months | J40: =IF(Inputs!$B$24="","",Inputs!$B$24) | K40: =IF(OR(Inputs!$B$16="",F40="",J40=""),"TBD",F40*J40) | L40: =IF(OR(Inputs!$B$16="",G40="",J40=""),"TBD",G40*J40) | M40: =IF(OR(Inputs!$B$16="",H40="",J40=""),"TBD",H40*J40) | N40: Decision required | O40: Inputs!B24 monthly cost × Inputs!B46 duration; providers/period TBD. | P40: Availability/retention/backup/licence terms verified. | Q40: Numeric target TBD unless approved. | R40: Хостинг, ліцензії та регулярні SaaS-витрати
...

Sheet Work_Packages
A1: Historical greenfield fixed-core packages — earlier scope only
A2: HISTORICAL REFERENCE: These Low/Base/High packages are not an estimate for the revised workflow. Do not use their totals as the current client budget or subtract unverified reuse hours.
A4: WBS ID | B4: Work package | C4: Included scope / completion outcome | D4: Dependencies | E4: Low person-hours | F4: Base person-hours | G4: High person-hours | H4: Status / source locator
A5: CORE-01 | B5: Discovery, product and security architecture | C5: Define user journeys, role/access matrix, domain model, acceptance scenarios, privacy rules and architecture decision record. Output: reviewed implementation backlog and unresolved-decision register. | D5: — | E5: 120 | F5: 160 | G5: 220 | H5: [ASSUMPTION]; source Pricing Model > Core Estimate, row 7.
A6: CORE-02 | B6: UX, design system and accessible responsive UI | C6: Design one-page network workspace, explicit mode/layer states, stacked panels, responsive touch layout, keyboard operation and bilingual UI. | D6: CORE-01 | E6: 100 | F6: 140 | G6: 190 | H6: [ASSUMPTION]; source Pricing Model > Core Estimate, row 8.
A7: CORE-03 | B7: Identity, authorization, consent and audit foundation | C7: Implement managed sign-in, role/scope checks, guest/member/operator/admin access, profile visibility/consent, contact separation and audit events. | D7: CORE-01 | E7: 180 | F7: 240 | G7: 330 | H7: [ASSUMPTION]; source Pricing Model > Core Estimate, row 9.
A8: CORE-04 | B8: Live data model and operator workspace | C8: Build schema, migrations, validation/import staging, provenance, deduplication review, correction workflow, operator queues and live graph APIs. Use synthetic/de-identified data until rights are approved. | D8: CORE-01, CORE-03 | E8: 180 | F8: 260 | G8: 380 | H8: [ASSUMPTION]; source Pricing Model > Core Estimate, row 10.
A9: CORE-05 | B9: Expert profiles and evidence-backed verification | C9: Implement profiles, evidence source/date/reviewer, verification states, provenance, corrections, appeal/review workflow and disclosure rules. No composite Trust/Influence score. | D9: CORE-03, CORE-04 | E9: 200 | F9: 290 | G9: 420 | H9: [ASSUMPTION]; source Pricing Model > Core Estimate, row 11.
A10: CORE-06 | B10: Expert search, filters and layered network graph | C10: Implement searchable profiles, sector/geography/topic filters, expert and feature layers, layer toggles, dependencies view, graph-to-dossier navigation and text-accessible equivalent. | D10: CORE-02, CORE-04, CORE-05 | E10: 180 | F10: 260 | G10: 380 | H10: [ASSUMPTION]; source Pricing Model > Core Estimate, row 12.
A11: CORE-07 | B11: Community collaboration and basic events | C11: Implement groups, member feed/posts, comments, shared resources, basic opportunities, event notices, moderation, delegated group administration and transactional email. No complex PM or E2EE. | D11: CORE-02, CORE-03, CORE-04 | E11: 220 | F11: 320 | G11: 470 | H11: [ASSUMPTION]; source Pricing Model > Core Estimate, row 13.
A12: CORE-08 | B12: Expert intake, recruitment and onboarding | C12: Implement consent-aware intake, campaign records, source tracking, candidate triage, human-reviewed verification handoff, onboarding and membership status. No autonomous AI decisions or social-platform automation. | D12: CORE-03, CORE-04, CORE-05, CORE-07 | E12: 160 | F12: 240 | G12: 360 | H12: [ASSUMPTION]; source Pricing Model > Core Estimate, row 14.
A13: CORE-09 | B13: Engagement operations and basic health analytics | C13: Implement group-owner tools, activity/participation measures, dormant-group signals, re-engagement tasks and basic role assignment workflow. No ranking or automatic privilege elevation. | D13: CORE-03, CORE-07, CORE-08 | E13: 140 | F13: 210 | G13: 320 | H13: [ASSUMPTION]; source Pricing Model > Core Estimate, row 15.
A14: CORE-10 | B14: Security hardening and privacy verification | C14: Threat-model core flows, verify authorization and minimization, configure secrets/encryption/secure defaults, test access/audit paths, prepare incident and retention controls. | D14: CORE-03, CORE-04, CORE-05, CORE-07, CORE-08, CORE-09 | E14: 80 | F14: 120 | G14: 180 | H14: [ASSUMPTION]; source Pricing Model > Core Estimate, row 16.
A15: CORE-11 | B15: Quality assurance, accessibility and acceptance testing | C15: Test role/data isolation, imports, graph interactions, workflows, failure paths, mobile/touch/keyboard and bilingual presentation; prepare acceptance scripts and regression coverage. | D15: CORE-02 through CORE-10 | E15: 180 | F15: 270 | G15: 400 | H15: [ASSUMPTION]; source Pricing Model > Core Estimate, row 17.
A16: CORE-12 | B16: Deployment, observability, backup and operational handover | C16: Create environments, CI/CD, monitoring/error logs, backup/restore checks, operational runbook and release handover. | D16: CORE-03, CORE-04, CORE-10, CORE-11 | E16: 100 | F16: 150 | G16: 230 | H16: [ASSUMPTION]; source Pricing Model > Core Estimate, row 18.
A17: CORE-13 | B17: Delivery management and client acceptance | C17: Coordinate dependencies, decisions, demonstrations, review cycles, issue triage, scope control and handover documentation through acceptance. | D17: CORE-01 through CORE-12 | E17: 100 | F17: 150 | G17: 240 | H17: [ASSUMPTION]; source Pricing Model > Core Estimate, row 19.
A18: TOTAL — fixed core | E18: =SUM(E5:E17) | F18: =SUM(F5:F17) | G18: =SUM(G5:G17) | H18: Formula totals of assumption inputs; source workbook Core Estimate rows 7–19.

Sheet Budget_Model
A1: Historical greenfield sensitivity, allocation checks and residual economics
A2: HISTORICAL REFERENCE ONLY — rate sensitivities below use the earlier 13-package Low/Base/High estimate; they are not a revised-scope quote or current client price.
A3: A. Historical published-rate sensitivity — not a revised-scope proposal price
A4: Effort case | B4: Person-hours | C4: Ukraine low ($/h) | D4: Ukraine high ($/h) | E4: Ukraine low sensitivity (USD) | F4: Ukraine high sensitivity (USD) | G4: US low ($/h) | H4: US high ($/h) | I4: US low sensitivity (USD) | J4: US high sensitivity (USD)
A5: Low | B5: =Work_Packages!E18 | C5: =Inputs!B4 | D5: =Inputs!B5 | E5: =B5*C5 | F5: =B5*D5 | G5: =Inputs!B6 | H5: =Inputs!B7 | I5: =B5*G5 | J5: =B5*H5
A6: Base | B6: =Work_Packages!F18 | C6: =Inputs!B4 | D6: =Inputs!B5 | E6: =B6*C6 | F6: =B6*D6 | G6: =Inputs!B6 | H6: =Inputs!B7 | I6: =B6*G6 | J6: =B6*H6
A7: High | B7: =Work_Packages!G18 | C7: =Inputs!B4 | D7: =Inputs!B5 | E7: =B7*C7 | F7: =B7*D7 | G7: =Inputs!B6 | H7: =Inputs!B7 | I7: =B7*G7 | J7: =B7*H7
A9: Interpretation | B9: Formula: assumed person-hours × published provider rate endpoint. These figures omit confirmed partner fees, selected implementation location, taxes, contingency, FX, hosting, licences, AI usage, recurring support, and profit. They are sensitivity examples, not a complete project budget.
A12: B. Target allocation ranges — do not sum endpoints as a final budget
A13: Contract currency and total budget | B13: =IF(OR(Inputs!B16="",Inputs!B17=""),"TBD",Inputs!B16&" "&TEXT(Inputs!B17,"0.00")) | D13: Selected developer share within target band | E13: =IF(Inputs!B25="","TBD",IF(OR(Inputs!B25<Inputs!B8,Inputs!B25>Inputs!B9),"OUTSIDE TARGET","WITHIN TARGET"))
A14: Developer target — lower | B14: =IF(OR(Inputs!B16="",Inputs!B17=""),"TBD",Inputs!B17*Inputs!B8) | D14: Selected operations share within target band | E14: =IF(Inputs!B26="","TBD",IF(OR(Inputs!B26<Inputs!B10,Inputs!B26>Inputs!B11),"OUTSIDE TARGET","WITHIN TARGET"))
A15: Developer target — upper | B15: =IF(OR(Inputs!B16="",Inputs!B17=""),"TBD",Inputs!B17*Inputs!B9) | D15: Combined minimum target share | E15: =Inputs!B8+Inputs!B10
A16: Core team / admin / relationships / representation — lower | B16: =IF(OR(Inputs!B16="",Inputs!B17=""),"TBD",Inputs!B17*Inputs!B10) | D16: Combined maximum target share | E16: =Inputs!B9+Inputs!B11
A17: Core team / admin / relationships / representation — upper | B17: =IF(OR(Inputs!B16="",Inputs!B17=""),"TBD",Inputs!B17*Inputs!B11) | D17: Profit/reinvestment ceiling | E17: =Inputs!B12
A18: Target-band envelope, both categories at minimum | B18: =Inputs!B8+Inputs!B10 | D18: Allocation note | E18: The maximum developer and operations target bands already sum to the full budget. Any profit/reinvestment is only a share of positive residual after verified costs; it is not an extra allocation on top.
A19: Target-band envelope, both categories at maximum | B19: =Inputs!B9+Inputs!B11
A20: Unallocated share at selected targets (not profit) | B20: =IF(OR(Inputs!B25="",Inputs!B26=""),"TBD",IF(Inputs!B25+Inputs!B26>1,"OVER 100%",1-Inputs!B25-Inputs!B26))
A21: C. Actual costs and residual — profit/reinvestment only after verified costs
A22: Verified direct-cost subtotal | B22: =IF(OR(Inputs!B18="",Inputs!B19="",Inputs!B20="",Inputs!B21="",Inputs!B30=""),"TBD",SUM(Inputs!B18:B21,Inputs!B30))
A23: Residual after verified costs | B23: =IF(OR(Inputs!B16="",Inputs!B17="",Inputs!B18="",Inputs!B19="",Inputs!B20="",Inputs!B21="",Inputs!B30=""),"TBD",Inputs!B17-SUM(Inputs!B18:B21,Inputs!B30))
A24: Residual state | B24: =IF(B23="TBD","TBD",IF(B23<0,"OVER BUDGET",IF(B23=0,"NO RESIDUAL","POSITIVE RESIDUAL")))
A25: Approved share / reinvestment amount | B25: =IF(OR(B23="TBD",Inputs!B22=""),"TBD",IF(Inputs!B22>Inputs!B12,"REVIEW: above unapproved ceiling",IF(B23<=0,"NO POSITIVE RESIDUAL",B23*Inputs!B22)))
A26: Optional community-service runway ceiling | B26: =IF(Inputs!B23="","TBD",Inputs!B23*Inputs!B15)
A27: Optional SaaS operating cost input | B27: =IF(Inputs!B24="","TBD",Inputs!B24)
A29: D. Payment schedule check
A30: Payment shares: 1 / 2 / 3 | B30: =IF(OR(Inputs!B16="",Inputs!B17="",Inputs!B27=""),"TBD",SUM(Inputs!B27:B29))
A31: Payment schedule status | B31: =IF(OR(Inputs!B16="",Inputs!B17="",Inputs!B27=""),"TBD",IF(OR(Inputs!B27<0,Inputs!B27>1,AND(Inputs!B28<>"",OR(Inputs!B28<0,Inputs!B28>1)),AND(Inputs!B29<>"",OR(Inputs!B29<0,Inputs!B29>1))),"CHECK SHARE RANGE",IF(AND(Inputs!B29<>"",Inputs!B28=""),"PAYMENTS MUST BE IN ORDER",IF(SUM(Inputs!B27:B29)<>1,"CHECK TOTAL = 100%",IF(Inputs!B27<Inputs!B13,"ADVANCE BELOW MINIMUM","OK — within 3-payment cap")))))
A33: Historical sensitivity uses USD company-directory rates and earlier package hours only; it is not the current budget. The UK contractor comparison below is shown separately in GBP. No market rate is selected as a project or partner rate.
A36: E. Market reference for discussion — not an input to the partner fee or client budget
A37: Jurisdiction | B37: Comparator class | C37: Low (source) | D37: High (source) | E37: Source unit | F37: Low normalized | G37: High normalized | H37: Normalized unit | I37: Formula / limitation | J37: Source and period
A38: United Kingdom | B38: Clutch provider-company rate | C38: Unknown | D38: Unknown | E38: USD/provider-hour | F38: — | G38: — | H38: Not available | I38: Clutch country-level provider data is explicitly Unknown; no UK agency rate is imputed. | J38: Source page
A39: United Kingdom | B39: Lorien software-engineer contractors | C39: =Market_Comparison!C8 | D39: =Market_Comparison!D8 | E39: GBP/contractor-day | F39: =Market_Comparison!F8 | G39: =Market_Comparison!G8 | H39: GBP/contractor-hour | I39: Normalize as GBP/contractor-day ÷ 7.5 hours/day; this is not an all-in provider-company price. | J39: Source page
A40: United States | B40: Clutch software-development provider companies | C40: =Market_Comparison!C5 | D40: =Market_Comparison!D5 | E40: USD/provider-hour | F40: — | G40: — | H40: USD/provider-hour | I40: Directory band only; not a matched supplier quote. No FX conversion to GBP. | J40: Source page
A41: Ukraine | B41: Clutch software-development provider companies | C41: =Market_Comparison!C6 | D41: =Market_Comparison!D6 | E41: USD/provider-hour | F41: — | G41: — | H41: USD/provider-hour | I41: Directory band only; not a matched supplier quote. No FX conversion to GBP. | J41: Source page
A43: These are market comparators only. No project price is calculated from them. A client budget requires the reconciled scope, selected supplier quote, agreed partner fees, confirmed external costs and a contract currency; the UK contractor/day-rate class is not directly comparable to US/Ukraine provider-company listings.
A45: F. Existing demo module — partner fee to agree; payable only after first client payment is received
A46: Module / scope | B46: Agreed fee | C46: Currency | D46: Payment trigger | E46: Reuse condition | F46: First instalment amount (expected) | G46: Balance after fee if first instalment received | H46: Coverage check | I46: Decision status | J46: Input / caveat
A47: Search + group formation; excludes persistence, extended dossier and project management | B47: =IF(Inputs!B30="","TBD",Inputs!B30) | C47: =IF(Inputs!B30="","TBD",IF(Inputs!B16="","TBD",Inputs!B16)) | D47: Pay the demo author only after receipt of the first client payment. | E47: Only if this module is reused in the application; partners must agree fee and reuse boundary. | F47: =IF(OR(Inputs!B17="",Inputs!B27=""),"TBD",Inputs!B17*Inputs!B27) | G47: =IF(OR(Inputs!B17="",Inputs!B27="",Inputs!B30=""),"TBD",Inputs!B17*Inputs!B27-Inputs!B30) | H47: =IF(OR(Inputs!B17="",Inputs!B27="",Inputs!B30=""),"TBD",IF(Inputs!B17*Inputs!B27>=Inputs!B30,"Covered by first instalment","First instalment does not cover fee")) | I47: =IF(Inputs!B30="","PARTNER DECISION REQUIRED",IF(OR(Inputs!B16="",Inputs!B17="",Inputs!B27=""),"FEE ENTERED — COMPLETE CONTRACT INPUTS","FEE ENTERED — VERIFY AGREEMENT, REUSE AND RECEIPT")) | J47: Inputs!B30; amount intentionally blank until agreed. Expected instalment is not proof of receipt.
A49: Accounting rule: enter this one-time demo reuse fee separately in Inputs!B30 and exclude it from Inputs!B19. The fee is included once in verified direct costs/residual calculations when agreed; it is not an extra client charge on top of the agreed contract total. Do not treat the expected first instalment as received cash.

Sheet Source_Register
A1: Model-local source register — not the canonical project registry
A3: Code | B3: Value / formula | C3: Unit | D3: Period | E3: Status | F3: Origin / locator | G3: Formula / method | H3: Connectedness | I3: Limit / caveat | J3: Evidence tier/class
A4: EFFORT-LOW | B4: =Work_Packages!E18 | C4: person-hours | D4: one-time fixed-core slice | E4: [ASSUMPTION] | F4: Source pricing workbook > Core Estimate, rows 7–19 | G4: SUM low-hour inputs | H4: Rate sensitivity by low/base/high scope | I4: No reuse credit for current code; no schedule implied. | J4: Tier 5 — legacy internal assumption/source workbook
A5: EFFORT-BASE | B5: =Work_Packages!F18 | C5: person-hours | D5: one-time fixed-core slice | E5: [ASSUMPTION] | F5: Source pricing workbook > Core Estimate, rows 7–19 | G5: SUM base-hour inputs | H5: Rate sensitivity by low/base/high scope | I5: No reuse credit for current code; no schedule implied. | J5: Tier 5 — legacy internal assumption/source workbook
A6: EFFORT-HIGH | B6: =Work_Packages!G18 | C6: person-hours | D6: one-time fixed-core slice | E6: [ASSUMPTION] | F6: Source pricing workbook > Core Estimate, rows 7–19 | G6: SUM high-hour inputs | H6: Rate sensitivity by low/base/high scope | I6: No reuse credit for current code; no schedule implied. | J6: Tier 5 — legacy internal assumption/source workbook
A7: UA-RATE-LOW | B7: =Inputs!B4 | C7: USD/provider-hour | D7: Clutch published 2026 band | E7: Source-reported | F7: Clutch pricing guide, updated Sep 2026 | G7: Published country band endpoint | H7: Ukraine-rate sensitivity, not final fee | I7: Not a national floor or matched quote. | J7: Tier 4 — private provider directory
A8: UA-RATE-HIGH | B8: =Inputs!B5 | C8: USD/provider-hour | D8: Clutch published 2026 band | E8: Source-reported | F8: Clutch pricing guide, updated Sep 2026 | G8: Published country band endpoint | H8: Ukraine-rate sensitivity, not final fee | I8: Not a national ceiling or matched quote. | J8: Tier 4 — private provider directory
A9: US-RATE-LOW | B9: =Inputs!B6 | C9: USD/provider-hour | D9: Clutch published 2026 band | E9: Source-reported | F9: Clutch pricing guide, updated Sep 2026 | G9: Published country band endpoint | H9: US comparative sensitivity only | I9: Not a national floor or matched quote. | J9: Tier 4 — private provider directory
A10: US-RATE-HIGH | B10: =Inputs!B7 | C10: USD/provider-hour | D10: Clutch published 2026 band | E10: Source-reported | F10: Clutch pricing guide, updated Sep 2026 | G10: Published country band endpoint | H10: US comparative sensitivity only | I10: Not a national ceiling or matched quote. | J10: Tier 4 — private provider directory
A11: DEV-SHARE | B11: =TEXT(Inputs!B8,"0%")&"–"&TEXT(Inputs!B9,"0%") | C11: fraction of agreed budget | D11: per project | E11: User-stated target; uncontracted | F11: Current conversation | G11: 33%–50% target band | H11: Allocation scenario only | I11: Not fees or an approved contract split. | J11: User input/unapproved decision; no external tier
A12: OPS-SHARE | B12: =TEXT(Inputs!B10,"0%")&"–"&TEXT(Inputs!B11,"0%") | C12: fraction of agreed budget | D12: per project | E12: User-stated target; uncontracted | F12: Current conversation | G12: 33%–50% target band | H12: Allocation scenario only | I12: Not fees or an approved contract split. | J12: User input/unapproved decision; no external tier
A13: PROFIT-CEILING | B13: =Inputs!B12 | C13: fraction of positive residual | D13: post verified costs | E13: Unapproved decision; inactive | F13: Current conversation | G13: No distribution/reinvestment formula until approved | H13: Residual-profit decision only | I13: Not applied to project budget; denominator is not total contract. | J13: User input/unapproved decision; no external tier
A14: ADVANCE-MIN | B14: =Inputs!B13 | C14: fraction of contract total | D14: per contract | E14: User-approved constraint; uncontracted | F14: Current conversation | G14: Advance must be >= this share | H14: Payment schedule check | I14: Milestone shares remain TBD. | J14: User input/unapproved decision; no external tier
A15: PAYMENT-CAP | B15: =Inputs!B14 | C15: payments | D15: per contract | E15: User-approved constraint; uncontracted | F15: Current conversation | G15: At most this many installments | H15: Three payment input slots | I15: Does not set payment triggers. | J15: User input/unapproved decision; no external tier
A16: OPS-RUNWAY-CAP | B16: =Inputs!B15 | C16: calendar months | D16: post-launch support scenario | E16: User-stated cap; not funded | F16: Current conversation | G16: monthly operations cost × cap, once known | H16: Optional runway scenario | I16: No monthly cost or approval is assumed. | J16: User input/unapproved decision; no external tier
A17: DOSSIER-LOW | B17: =Revised_Scope!B27 | C17: possible dossiers (people) | D17: planning scenario | E17: [ASSUMPTION] user-provided range boundary | F17: Current user direction; possible 300–500 dossier cohort | G17: Lower scenario input = 300; no inference from group size or conversion | H17: Feeds dossier workload hours and variable-cost scenarios | I17: Not a verified expert count, reachable audience, opt-in count, or forecast. | J17: User-provided scenario/assumption
A18: DOSSIER-MID | B18: =Revised_Scope!B28 | C18: possible dossiers (people) | D18: planning scenario | E18: [ASSUMPTION] arithmetic midpoint | F18: Current user direction; possible 300–500 dossier cohort | G18: (300 + 500) / 2 = 400; formula in Revised_Scope!B28 | H18: Feeds dossier workload hours and variable-cost scenarios | I18: Midpoint is not a forecast or expected participation. | J18: User-provided scenario/assumption
A19: DOSSIER-HIGH | B19: =Revised_Scope!B29 | C19: possible dossiers (people) | D19: planning scenario | E19: [ASSUMPTION] user-provided range boundary | F19: Current user direction; possible 300–500 dossier cohort | G19: Upper scenario input = 500; no inference from group size or conversion | H19: Feeds dossier workload hours and variable-cost scenarios | I19: Not a verified expert count, reachable audience, opt-in count, or forecast. | J19: User-provided scenario/assumption
A20: TI-PREP-DAYS | B20: 2–3 | C20: working days | D20: preparation for Trust & Influence strategic session | E20: User-stated; not independently verified | F20: Current user direction | G20: 2–3 working days; hours shown only under explicit 8 h/day × 1 person assumptions in Partner_Effort. | H20: Separate partner consulting effort; excluded from dossier calculator | I20: Does not include the session, synthesis, model/protocol drafting, validation, or training. | J20: User-provided scenario/assumption
A21: UK-CLUTCH | B21: Unknown | C21: USD/provider-hour | D21: Clutch pricing guide updated 21 Sep 2026 | E21: Source-reported; unavailable | F21: https://clutch.co/developers/pricing | G21: UK country-level provider rate is explicitly Unknown; do not impute it. | J21: Tier 4 — provider directory
A22: UK-CTR-LOW | B22: 400 | C22: GBP/contractor-day | D22: Lorien 2026 guide | E22: Source-reported | F22: https://www.lorienglobal.com/insights/software-developer-contract-rates-in-the-uk | G22: Software engineer contractor range low endpoint; not an agency/provider quote. | J22: Tier 4 — contractor guide
